Workbook
Name Срез_GURUHI: #N/A
Name Срез_Guruhi1: #N/A
Name Срез_GURUHI10: #N/A
Name Срез_GURUHI2: #N/A
Name Срез_GURUHI3: #N/A
Name Срез_GURUHI4: #N/A
Name Срез_GURUHI5: #N/A
Name Срез_GURUHI6: #N/A
Name Срез_GURUHI7: #N/A
Name Срез_GURUHI8: #N/A
Name Срез_GURUHI9: #N/A

Sheet KONTRAKTLAR
C1: Guruh rahbari | D1: Guruh | E1: Talabalar soni | F1: Qarzdorligi
C2: Rahmatova.Sh | D2: 24-11 | E2: =COUNTIF($A$19:$A$1040,D2) -> 27 | F2: =SUMIFS(F:F, A:A, D2, F:F, ">0") -> 25913074
C3: Botirova.G | D3: 24-12 | E3: =COUNTIF($A$19:$A$1040,D3) -> 24 | F3: =SUMIFS(F:F, A:A, D3, F:F, ">0") -> 28900000
C4: Elmurodova.N | D4: 24-13 | E4: =COUNTIF($A$19:$A$1040,D4) -> 24 | F4: =SUMIFS(F:F, A:A, D4, F:F, ">0") -> 19959500
C5: Asraliyev.A | D5: 24-15 | E5: =COUNTIF($A$19:$A$1040,D5) -> 22 | F5: =SUMIFS(F:F, A:A, D5, F:F, ">0") -> 5600000
C6: Yuldashev.O | D6: 24-16 | E6: =COUNTIF($A$19:$A$1040,D6) -> 18 | F6: =SUMIFS(F:F, A:A, D6, F:F, ">0") -> 23601000
C7: Xidirova.N | D7: 25-16 | E7: =COUNTIF($A$19:$A$1040,D7) -> 27 | F7: =SUMIFS(F:F, A:A, D7, F:F, ">0") -> 20116500
C8: Meyliyev.B | D8: 25-17 | E8: =COUNTIF($A$19:$A$1040,D8) -> 23 | F8: =SUMIFS(F:F, A:A, D8, F:F, ">0") -> 23723000
C9: Eshnayev.B | D9: 25-18 | E9: =COUNTIF($A$19:$A$1040,D9) -> 25 | F9: =SUMIFS(F:F, A:A, D9, F:F, ">0") -> 29181743
C10: Shukurova.G | D10: 25-19 | E10: =COUNTIF($A$19:$A$1040,D10) -> 26 | F10: =SUMIFS(F:F, A:A, D10, F:F, ">0") -> 26133500
C11: Maxamadiyev.L | D11: 25-20 | E11: =COUNTIF($A$19:$A$1040,D11) -> 25 | F11: =SUMIFS(F:F, A:A, D11, F:F, ">0") -> 20779000
C12: Eshnayev.B | D12: 25-21 | E12: =COUNTIF($A$19:$A$1040,D12) -> 30 | F12: =SUMIFS(F:F, A:A, D12, F:F, ">0") -> 47321000
C13: Rahmatova.Sh | D13: 25-22 | E13: =COUNTIF($A$19:$A$1040,D13) -> 28 | F13: =SUMIFS(F:F, A:A, D13, F:F, ">0") -> 24875500
C14: Quldosheva.K | D14: 25-23 | E14: =COUNTIF($A$19:$A$1040,D14) -> 23 | F14: =SUMIFS(F:F, A:A, D14, F:F, ">0") -> 33126000
C15: Jami | E15: =SUM(E2:E14) -> 322 | F15: =SUM(F2:F14) -> 3.2922982e+08
C17: Yangilangan sanasi: | D17: 02.10.2026
A18: GURUHI | B18: № | C18: Familiiyasi Ismi va Sharfi | D18: Shu vaqtgacha bo'lishi kerak bo'lgan to'lov | E18: Jami | F18: Shu vaqtgacha qarzi
A19: 25-21 | B19: =COUNTIF($A$19:A19,A19) -> 1 | C19: Raxmonova Mahbuba Tolib qizi | D19: =8500000+1700000 -> 10200000 | E19: 0 | F19: =D19-E19 -> 10200000
A20: 25-22 | B20: =COUNTIF($A$19:A20,A20) -> 1 | C20: Ochilova Shahlo Nematullayevna | D20: =8500000+1700000 -> 10200000 | E20: =0+4000000 -> 4000000 | F20: =D20-E20 -> 6200000
A21: 25-23 | B21: =COUNTIF($A$19:A21,A21) -> 1 | C21: Sanayeva Iroda Kuchkor qizi | D21: =8500000+1700000 -> 10200000 | E21: =4500000 -> 4500000 | F21: =D21-E21 -> 5700000
A22: 25-23 | B22: =COUNTIF($A$19:A22,A22) -> 2 | C22: Sunnatillayeva Eʼzoza | D22: =8500000+1700000 -> 10200000 | E22: =5000000 -> 5000000 | F22: =D22-E22 -> 5200000
A23: 24-16 | B23: =COUNTIF($A$19:A23,A23) -> 1 | C23: Ergasheva Gulnoza Jamol qizi | D23: =2*8500000*3/4 -> 12750000 | E23: =4250000+600000+600000+900000+900000+1250000 -> 8500000 | F23: =D23-E23 -> 4250000
A24: 25-19 | B24: =COUNTIF($A$19:A24,A24) -> 1 | C24: Jamshidova Sug'diyona Jamshir qizi | D24: =8500000+1700000 -> 10200000 | E24: =0+1000000+1000000+1500000+1387500+1000000 -> 5887500 | F24: =D24-E24 -> 4312500
A25: 25-17 | B25: =COUNTIF($A$19:A25,A25) -> 1 | C25: Rahmonov Ravshan Rafiuqovich | D25: =8500000+1700000 -> 10200000 | E25: =1640000+2000000+1183000+1078000 -> 5901000 | F25: =D25-E25 -> 4299000
A26: 24-16 | B26: =COUNTIF($A$19:A26,A26) -> 2 | C26: Muxammadiyeva Xurshida Ismatovna | D26: =2*8500000*3/4 -> 12750000 | E26: =1275000+3000000+1200000+1500000+1600000 -> 8575000 | F26: =D26-E26 -> 4175000
A27: 24-16 | B27: =COUNTIF($A$19:A27,A27) -> 3 | C27: Sharifova Nozima Husanova | D27: =2*8500000*3/4 -> 12750000 | E27: =2275000+1196000+1006000+1923000+2100000+850000 -> 9350000 | F27: =D27-E27 -> 3400000
A28: 25-19 | B28: =COUNTIF($A$19:A28,A28) -> 2 | C28: O'ktamova Sarvinoz Obid qizi | D28: =8500000+1700000 -> 10200000 | E28: =4250000+2125000 -> 6375000 | F28: =D28-E28 -> 3825000
A29: 24-15 | B29: =COUNTIF($A$19:A29,A29) -> 1 | C29: Rashidova Shahzoda Suyun qizi | D29: =2*8500000*3/4 -> 12750000 | E29: 9200000 | F29: =D29-E29 -> 3550000
A30: 25-18 | B30: =COUNTIF($A$19:A30,A30) -> 1 | C30: Usmonova Sabrina Akrom qizi | D30: =8500000+1700000 -> 10200000 | E30: =1238000+1800000+1100000+2516000 -> 6654000 | F30: =D30-E30 -> 3546000
A31: 24-16 | B31: =COUNTIF($A$19:A31,A31) -> 4 | C31: O'roqova Nilufar Nasrullo qizi | D31: =2*8500000*3/4 -> 12750000 | E31: 10500000 | F31: =D31-E31 -> 2250000
A32: 25-16 | B32: =COUNTIF($A$19:A32,A32) -> 1 | C32: Yarasheva Ruxshonaoy Uchqun qizi | D32: =8500000+1700000 -> 10200000 | E32: =1300000+1806250+1800000+2000000 -> 6906250 | F32: =D32-E32 -> 3293750
A33: 25-16 | B33: =COUNTIF($A$19:A33,A33) -> 2 | C33: To'xliyeva Nilufar Baxtiyor qizi | D33: =8500000+1700000 -> 10200000 | E33: 8575000 | F33: =D33-E33 -> 1625000
A34: 25-21 | B34: =COUNTIF($A$19:A34,A34) -> 2 | C34: Rajabova Gulnora Amirovna | D34: =8500000+1700000 -> 10200000 | E34: =0+1700000+1700000+3500000+850000 -> 7750000 | F34: =D34-E34 -> 2450000
A35: 24-16 | B35: =COUNTIF($A$19:A35,A35) -> 5 | C35: Yunusova Qurbonoy Kamol qizi | D35: =2*8500000*3/4 -> 12750000 | E35: =4890000+2500000+1110000+2125000 -> 10625000 | F35: =D35-E35 -> 2125000
A36: 24-16 | B36: =COUNTIF($A$19:A36,A36) -> 6 | C36: Allayorova Diyora Abdusalom qizi | D36: =2*8500000*3/4 -> 12750000 | E36: 10700000 | F36: =D36-E36 -> 2050000
A37: 25-23 | B37: =COUNTIF($A$19:A37,A37) -> 3 | C37: Ibodova Parvina Abdurashid qizi | D37: =8500000+1700000 -> 10200000 | E37: 8000000 | F37: =D37-E37 -> 2200000
A38: 24-16 | B38: =COUNTIF($A$19:A38,A38) -> 7 | C38: Meliqulova Shalola Amonovna | D38: =2*8500000*3/4 -> 12750000 | E38: =3082000+1300000+2200000+1920000+2225000 -> 10727000 | F38: =D38-E38 -> 2023000
A39: 25-19 | B39: =COUNTIF($A$19:A39,A39) -> 3 | C39: Muxammedova E'zoza Sodiq qizi | D39: =8500000+1700000 -> 10200000 | E39: =0+1200000+1200000+600000+2000000+1800000+1300000 -> 8100000 | F39: =D39-E39 -> 2100000
A40: 24-16 | B40: =COUNTIF($A$19:A40,A40) -> 8 | C40: Oqmirzayeva Jumagul Abdulla qizi | D40: =2*8500000*3/4 -> 12750000 | E40: =2522000+2500000+3500000+2400000 -> 10922000 | F40: =D40-E40 -> 1828000
A41: 24-16 | B41: =COUNTIF($A$19:A41,A41) -> 9 | C41: Sattorova Sevinch Otabek qizi | D41: =2*8500000*3/4 -> 12750000 | E41: 12000000 | F41: =D41-E41 -> 750000
...

Sheet yil yakuniga qadar
A1: T/R | B1: Kursi | C1: Guruhi | D1: Talabalar soni | E1: Shartnoma summasi | F1: To'lagan summasi | G1: Qarzi
A2: 1 | B2: 2 | C2: =KONTRAKTLAR!D2 -> 24-11 | D2: =KONTRAKTLAR!E2 -> 27 | E2: =IF(B2=1,8500000,IF(B2=2,17000000,""))*D2 -> 459000000 | F2: =SUMIFS(KONTRAKTLAR!E:E, KONTRAKTLAR!A:A, 'yil yakuniga qadar'!C2, KONTRAKTLAR!E:E, ">0") -> 4.9088793e+08 | G2: =E2-F2 -> -31887926
A3: 2 | B3: 2 | C3: =KONTRAKTLAR!D3 -> 24-12 | D3: =KONTRAKTLAR!E3 -> 24 | E3: =IF(B3=1,8500000,IF(B3=2,17000000,""))*D3 -> 408000000 | F3: =SUMIFS(KONTRAKTLAR!E:E, KONTRAKTLAR!A:A, 'yil yakuniga qadar'!C3, KONTRAKTLAR!E:E, ">0") -> 419953500 | G3: =E3-F3 -> -11953500
A4: 3 | B4: 2 | C4: =KONTRAKTLAR!D4 -> 24-13 | D4: =KONTRAKTLAR!E4 -> 24 | E4: =IF(B4=1,8500000,IF(B4=2,17000000,""))*D4-8500000 -> 399500000 | F4: =SUMIFS(KONTRAKTLAR!E:E, KONTRAKTLAR!A:A, 'yil yakuniga qadar'!C4, KONTRAKTLAR!E:E, ">0") -> 421947750 | G4: =E4-F4 -> -22447750
A5: 4 | B5: 2 | C5: =KONTRAKTLAR!#REF! -> #REF! | D5: =KONTRAKTLAR!#REF! -> #REF! | E5: =IF(B5=1,8500000,IF(B5=2,17000000,""))*D5-21250000 -> #REF! | F5: =SUMIFS(KONTRAKTLAR!E:E, KONTRAKTLAR!A:A, 'yil yakuniga qadar'!C5, KONTRAKTLAR!E:E, ">0") -> 0 | G5: =SUMIFS(KONTRAKTLAR!F:F, KONTRAKTLAR!A:A, 'yil yakuniga qadar'!C5, KONTRAKTLAR!F:F, ">0") -> 0
A6: 5 | B6: 2 | C6: =KONTRAKTLAR!D5 -> 24-15 | D6: =KONTRAKTLAR!E5 -> 22 | E6: =IF(B6=1,8500000,IF(B6=2,17000000,""))*D6 -> 374000000 | F6: =SUMIFS(KONTRAKTLAR!E:E, KONTRAKTLAR!A:A, 'yil yakuniga qadar'!C6, KONTRAKTLAR!E:E, ">0") -> 302552000 | G6: =E6-F6 -> 71448000
A7: 6 | B7: 2 | C7: =KONTRAKTLAR!D6 -> 24-16 | D7: =KONTRAKTLAR!E6 -> 18 | E7: =IF(B7=1,8500000,IF(B7=2,17000000,""))*D7 -> 306000000 | F7: =SUMIFS(KONTRAKTLAR!E:E, KONTRAKTLAR!A:A, 'yil yakuniga qadar'!C7, KONTRAKTLAR!E:E, ">0") -> 219109000 | G7: =E7-F7 -> 86891000
A8: 7 | B8: 1 | C8: =KONTRAKTLAR!D7 -> 25-16 | D8: =KONTRAKTLAR!E7 -> 27 | E8: =IF(B8=1,8500000,IF(B8=2,17000000,""))*D8 -> 229500000 | F8: =SUMIFS(KONTRAKTLAR!E:E, KONTRAKTLAR!A:A, 'yil yakuniga qadar'!C8, KONTRAKTLAR!E:E, ">0") -> 237897100 | G8: =E8-F8 -> -8397100
A9: 8 | B9: 1 | C9: =KONTRAKTLAR!D8 -> 25-17 | D9: =KONTRAKTLAR!E8 -> 23 | E9: =IF(B9=1,8500000,IF(B9=2,17000000,""))*D9 -> 195500000 | F9: =SUMIFS(KONTRAKTLAR!E:E, KONTRAKTLAR!A:A, 'yil yakuniga qadar'!C9, KONTRAKTLAR!E:E, ">0") -> 211283000 | G9: =E9-F9 -> -15783000
A10: 9 | B10: 1 | C10: =KONTRAKTLAR!D9 -> 25-18 | D10: =KONTRAKTLAR!E9 -> 25 | E10: =IF(B10=1,8500000,IF(B10=2,17000000,""))*D10 -> 212500000 | F10: =SUMIFS(KONTRAKTLAR!E:E, KONTRAKTLAR!A:A, 'yil yakuniga qadar'!C10, KONTRAKTLAR!E:E, ">0") -> 229929257 | G10: =E10-F10 -> -17429257
A11: 10 | B11: 1 | C11: =KONTRAKTLAR!D10 -> 25-19 | D11: =KONTRAKTLAR!E10 -> 26 | E11: =IF(B11=1,8500000,IF(B11=2,17000000,""))*D11 -> 221000000 | F11: =SUMIFS(KONTRAKTLAR!E:E, KONTRAKTLAR!A:A, 'yil yakuniga qadar'!C11, KONTRAKTLAR!E:E, ">0") -> 244814000 | G11: =E11-F11 -> -23814000
A12: 11 | B12: 1 | C12: =KONTRAKTLAR!D11 -> 25-20 | D12: =KONTRAKTLAR!E11 -> 25 | E12: =IF(B12=1,8500000,IF(B12=2,17000000,""))*D12 -> 212500000 | F12: =SUMIFS(KONTRAKTLAR!E:E, KONTRAKTLAR!A:A, 'yil yakuniga qadar'!C12, KONTRAKTLAR!E:E, ">0") -> 240748250 | G12: =E12-F12 -> -28248250
A13: 12 | B13: 1 | C13: =KONTRAKTLAR!D12 -> 25-21 | D13: =KONTRAKTLAR!E12 -> 30 | E13: =IF(B13=1,8500000,IF(B13=2,17000000,""))*D13 -> 255000000 | F13: =SUMIFS(KONTRAKTLAR!E:E, KONTRAKTLAR!A:A, 'yil yakuniga qadar'!C13, KONTRAKTLAR!E:E, ">0") -> 264879000 | G13: =E13-F13 -> -9879000
A14: 13 | B14: 1 | C14: =KONTRAKTLAR!D13 -> 25-22 | D14: =KONTRAKTLAR!E13 -> 28 | E14: =IF(B14=1,8500000,IF(B14=2,17000000,""))*D14-3*1500000 -> 233500000 | F14: =SUMIFS(KONTRAKTLAR!E:E, KONTRAKTLAR!A:A, 'yil yakuniga qadar'!C14, KONTRAKTLAR!E:E, ">0") -> 260448000 | G14: =E14-F14 -> -26948000
A15: 14 | B15: 1 | C15: =KONTRAKTLAR!D14 -> 25-23 | D15: =KONTRAKTLAR!E14 -> 23 | E15: =IF(B15=1,8500000,IF(B15=2,17000000,""))*D15 -> 195500000 | F15: =SUMIFS(KONTRAKTLAR!E:E, KONTRAKTLAR!A:A, 'yil yakuniga qadar'!C15, KONTRAKTLAR!E:E, ">0") -> 201737000 | G15: =E15-F15 -> -6237000
A16: JAMI: | D16: =SUM(D2:D15) -> #REF! | E16: =SUM(E2:E15) -> #REF! | F16: =SUM(F2:F15) -> 3.7461858e+09 | G16: =SUM(G2:G15) -> -44685783

Sheet Akademik.TSCH
A1: AKADEMIK & T.S.CH
A3: GURUHI | B3: № | C3: Familiiyasi Ismi va Sharfi | D3: Shu vaqtgacha bo'lishi kerak bo'lgan to'lov | E3: Jami | F3: Shu vaqtgacha qarzi
A4: 24-11 | B4: =COUNTIF($A4:A$5,A4) -> 2 | C4: Otaqulova Moxiniso Tursunpo'lat qizi | D4: =8500000+1700000+1700000 -> 11900000 | E4: =8550000 -> 8550000 | F4: =D4-E4 -> 3350000
A5: 24-11 | B5: =COUNTIF($A$5:A5,A5) -> 1 | C5: Nasimova Durdona Yormahmat qizi | D5: =8500000+1700000+1700000 -> 11900000 | E5: =8500000 -> 8500000 | F5: =D5-E5 -> 3400000
A6: 24-15 | B6: =COUNTIF($A$6:A6,A6) -> 1 | C6: To'g'izova Zahro Tohir qizi | D6: 8500000 | E6: =0 -> 0 | F6: =D6-E6 -> 8500000
A7: 24-12 | B7: =COUNTIF($A$7:A7,A7) -> 1 | C7: Husanova Rayhona Husan qizi | D7: =8500000+1700000+1700000 -> 11900000 | E7: =8500000 -> 8500000 | F7: =D7-E7 -> 3400000
A8: 24-13 | B8: =COUNTIF($A$8:A8,A8) -> 1 | C8: Numonova Feruza Mirhomid qizi | D8: =8500000+1700000+1700000 -> 11900000 | E8: =8501000 -> 8501000 | F8: =D8-E8 -> 3399000
A9: 24-14 | B9: =COUNTIF($A$9:A9,A9) -> 1 | C9: Shodiyeva Fayyoza Farxod qizi | D9: =8500000+1700000+1700000 -> 11900000 | E9: =8500000 -> 8500000 | F9: =D9-E9 -> 3400000
A10: 25-16 | B10: =COUNTIF($A$10:A10,A10) -> 1 | C10: Ergasheva Sevinch | D10: =1275000+1806250 -> 3081250 | E10: =1201000 -> 1201000 | F10: =D10-E10 -> 1880250
A11: 25-17 | B11: =COUNTIF($A$11:A11,A11) -> 1 | C11: Ziyodullayeva Zahro Ubaydullo qizi | D11: =1275000+1806250 -> 3081250 | E11: =0+1300000 -> 1300000 | F11: =D11-E11 -> 1781250
A12: 24-15 | B12: =COUNTIF($A$12:A12,A12) -> 1 | C12: Hasanova Gulsevar Lochinbek qizi | D12: 8500000 | E12: =3138000 -> 3138000 | F12: =D12-E12 -> 5362000
A13: 24-15 | B13: =COUNTIF($A$13:A13,A13) -> 1 | C13: Mahmudova Munisa Mahsudjonovna | D13: 8500000 | E13: =4000000 -> 4000000 | F13: =D13-E13 -> 4500000
A14: 25-18 | B14: =COUNTIF($A$14:A14,A14) -> 1 | C14: Xamrayeva Niginabonu Jamshid qizi | D14: =1275000+1806250 -> 3081250 | E14: =1000000+300000 -> 1300000 | F14: =D14-E14 -> 1781250
A15: 24-13 | B15: =COUNTIF($A$15:A15,A15) -> 1 | C15: Suyunova Ruxshona Karimjon qizi | D15: =8500000+1700000+1700000 -> 11900000 | E15: =1275000 -> 1275000 | F15: =D15-E15 -> 10625000
A16: 25-20 | B16: =COUNTIF($A$16:A16,A16) -> 1 | C16: Omonova Sumbula Farxod qizi | D16: =1275000+1806250 -> 3081250 | E16: =1275000 -> 1275000 | F16: =D16-E16 -> 1806250
A17: 24-13 | B17: =COUNTIF($A$17:A17,A17) -> 1 | C17: Norboboyeva Zahro Nuriddin qizi | D17: =8500000+1700000+1700000 -> 11900000 | E17: =8500000 -> 8500000 | F17: =D17-E17 -> 3400000
A18: 25-16 | B18: =COUNTIF($A$18:A18,A18) -> 1 | C18: G'abborova Xosiyat Nosir qizi | D18: =1275000+1806250+1806250 -> 4887500 | E18: =1275000 -> 1275000 | F18: =D18-E18 -> 3612500
A19: 25-17 | B19: =COUNTIF($A$19:A19,A19) -> 1 | C19: Usmonova Jasmina Nodir qizi | D19: =1275000+1806250+1806250 -> 4887500 | E19: =0+1500000 -> 1500000 | F19: =D19-E19 -> 3387500
A20: 25-19 | B20: =COUNTIF($A$20:A20,A20) -> 1 | C20: Soliyeva E'zoza | D20: =1275000+1806250+1806250 -> 4887500 | E20: =1300000+1900000 -> 3200000 | F20: =D20-E20 -> 1687500
A21: 25-19 | B21: =COUNTIF($A$20:A21,A21) -> 2 | C21: To'xtayeva Shirida Sirojiddin qizi | D21: =1275000+1806250+1806250 -> 4887500 | E21: =1275000+1810000 -> 3085000 | F21: =D21-E21 -> 1802500
A22: 25-19 | B22: =COUNTIF($A$20:A22,A22) -> 3 | C22: Usmonova Shabbona Botir qizi | D22: =1275000+1806250+1806250 -> 4887500 | E22: =1275000+1806250 -> 3081250 | F22: =D22-E22 -> 1806250
A23: 25-20 | B23: =COUNTIF($A$23:A23,A23) -> 1 | C23: Qarshiyeva Ruxshona Otabek qizi | D23: =1275000+1806250+1806250 -> 4887500 | E23: =1000000 -> 1000000 | F23: =D23-E23 -> 3887500
A24: 25-21 | B24: =COUNTIF($A$24:A24,A24) -> 1 | C24: Toshkentova Sevinch Zayniddinovna | D24: =1275000+1806250+1806250 -> 4887500 | E24: =1275000+1810000 -> 3085000 | F24: =D24-E24 -> 1802500
A25: 24-16 | B25: =COUNTIF($A$25:A25,A25) -> 1 | C25: O'ktamova Sarvinoz Obid qizi | D25: =4250000+2125000 -> 6375000 | E25: =4250000+2125000 -> 6375000 | F25: =D25-E25 -> 0
A26: 24-12 | B26: =COUNTIF($A$26:A26,A26) -> 1 | C26: Omonova Dilorom Toshkent qizi | D26: =8500000+1700000+1700000+1700000 -> 13600000 | E26: =8480000+4000000+1200000 -> 13680000 | F26: =D26-E26 -> -80000
A27: 24-12 | B27: =COUNTIF($A$27:A27,A27) -> 1 | C27: To'rayeva Elsenora Sobir qizi | D27: =8500000+1700000+1700000+1700000 -> 13600000 | E27: =8500000+1600000+2400000+900000 -> 13400000 | F27: =D27-E27 -> 200000
A28: 25-20 | B28: =COUNTIF($A$28:A28,A28) -> 1 | C28: Yusupova Asila Iskandar qizi | D28: =1275000+1806250+1806250+1806250 -> 6693750 | E28: =1300000+1810000+1200000 -> 4310000 | F28: =D28-E28 -> 2383750
A29: 25-20 | B29: =COUNTIF($A$29:A29,A29) -> 1 | C29: Saidaliyeva Sevinch | D29: =1275000+1806250+1806250+1806250 -> 6693750 | E29: =3000000 -> 3000000 | F29: =D29-E29 -> 3693750
A30: 24-14 | B30: =COUNTIF($A$30:A30,A30) -> 1 | C30: O'roqova Muslima Anvar qizi | D30: =8500000+1700000+1700000+1700000+1700000 -> 15300000 | E30: =8500000+2200000+2000000+1100000+1200000 -> 15000000 | F30: =D30-E30 -> 300000
A31: 25-22 | B31: =COUNTIF($A$31:A31,A31) -> 1 | C31: Abdukarimova Nafosat Faxriddin qizi | D31: =1275000+1806250+1806250+1806250 -> 6693750 | E31: 8500000 | F31: =D31-E31 -> -1806250
A32: 24-14 | B32: =COUNTIF($A$32:A32,A32) -> 1 | C32: Eshmuhammadova Yulduz Farhod qizi | D32: =8500000+1700000+1700000+1700000+1700000 -> 15300000 | E32: =5700000+2000000+3600000 -> 11300000 | F32: =D32-E32 -> 4000000
A33: 25-18 | B33: =COUNTIF($A$33:A33,A33) -> 1 | C33: Baxtiyorova Dinora Akmalovna | D33: =1275000+1806250+1806250+1806250 -> 6693750 | E33: =0+1270000+1806000+181200 -> 3257200 | F33: =D33-E33 -> 3436550
A34: 25-23 | B34: =COUNTIF($A$34:A34,A34) -> 1 | C34: Xusanboyeva Fotimaxon Baxtiyor qizi | D34: =1275000+1806250+1806250 -> 4887500 | E34: =2000000 -> 2000000 | F34: =D34-E34 -> 2887500
A35: 25-19 | B35: =COUNTIF($A$35:A35,A35) -> 1 | C35: Nishonova Hilola Faxriddin qizi | D35: =1275000+1806250+1806250+1806250+1806250 -> 8500000 | E35: =1280000+1807000+1850000 -> 4937000 | F35: =D35-E35 -> 3563000
A36: 25-19 | B36: =COUNTIF($A$36:A36,A36) -> 1 | C36: Azizova Asila Baxodirxon qizi | D36: =1275000+1806250+1806250+1806250+1806250 -> 8500000 | E36: =2125000+2000000+800000 -> 4925000 | F36: =D36-E36 -> 3575000
A37: 24-13 | B37: =COUNTIF($A$37:A37,A37) -> 1 | C37: Sayfullayeva Kumush Lutfullo qizi | D37: =8500000+1700000+1700000+1700000+1700000+1700000 -> 17000000 | E37: =11900000+1700000+2000000 -> 15600000 | F37: =Таблица1[[#This Row],[Shu vaqtgacha bo''lishi kerak bo''lgan to''lov]]-Таблица1[[#This Row],[Jami]] -> 2200000
A38: 25-23 | B38: =COUNTIF($A$38:A38,A38) -> 1 | C38: Jabborova Anora Nuriddin qizi | D38: 8500000 | E38: =1275000+1900000 -> 3175000 | F38: =Таблица1[[#This Row],[Shu vaqtgacha bo''lishi kerak bo''lgan to''lov]]-Таблица1[[#This Row],[Jami]] -> 2023000
A39: 25-16 | B39: 1 | C39: Raimova Zulfizar Rasulovna | D39: 8500000 | E39: 4000000 | F39: 4500000
A40: 25-16 | B40: 2 | C40: Abdualimova Nilufar Akbar qizi | D40: 8500000 | E40: 4100000 | F40: 4400000
A41: 25-16 | B41: 3 | C41: Meyliqulova Sabrina Baxtiyor qizi | D41: 8500000 | E41: 4475000 | F41: 4025000
...

Sheet Minuslar
A1: Guruhi | B1: I.F.O | C1: Minus summasi
A2: 25-22 | B2: Boymurodova Mushtariy Bosun qizi | C2: 1500000
A3: 25-22 | B3: Sattarova Gulasalbonu Sobir qizi | C3: 1500000
A4: 25-22 | B4: Xayrollayeva Ozoda Toshbova qizi | C4: 1500000
A5: 24-13 | B5: Jumaboyeva Sevinch Umid qizi | C5: 8500000
A6: 24-14 | B6: Karimova Ruxshona Homid qizi | C6: =3*4250000 -> 12750000
A7: 24-14 | B7: Ziyoviddinova Laylo Xurram qizi | C7: 8500000
A10: Итог | C10: =SUBTOTAL(109,Таблица2[Minus summasi]) -> 34250000

Sheet Bitirganlar
C1: Guruh rahbari | D1: Guruh | E1: Talabalar soni | F1: Qarzdorligi
C2: Yuldashev.O | D2: 114 | E2: =SUMIFS(F:F, A:A, D2, F:F, ">0") -> 0
C3: Yuldashev.O | D3: 115 | E3: =SUMIFS(F:F, A:A, D3, F:F, ">0") -> 15870000
C4: Rahmatova.Sh | D4: 116 | E4: =SUMIFS(F:F, A:A, D4, F:F, ">0") -> 5100000
C5: Rahmatova.Sh | D5: 24-11 | E5: =COUNTIF($A$23:$A$830,D5) -> 0 | F5: =SUMIFS(F:F, A:A, D5, F:F, ">0") -> 0
C6: Botirova.G | D6: 24-12 | E6: =COUNTIF($A$23:$A$830,D6) -> 0 | F6: =SUMIFS(F:F, A:A, D6, F:F, ">0") -> 0
C7: Elmurodova.N | D7: 24-13 | E7: =COUNTIF($A$23:$A$830,D7) -> 0 | F7: =SUMIFS(F:F, A:A, D7, F:F, ">0") -> 0
C8: Ochilov.D | D8: 24-14 | E8: =COUNTIF($A$23:$A$830,D8) -> 29 | F8: =SUMIFS(F:F, A:A, D8, F:F, ">0") -> 59
C9: Asraliyev.A | D9: 24-15 | E9: =COUNTIF($A$23:$A$830,D9) -> 0 | F9: =SUMIFS(F:F, A:A, D9, F:F, ">0") -> 0
C10: Yuldashev.O | D10: 24-16 | E10: =COUNTIF($A$23:$A$830,D10) -> 0 | F10: =SUMIFS(F:F, A:A, D10, F:F, ">0") -> 0
C11: Xidirova.N | D11: 25-16 | E11: =COUNTIF($A$23:$A$830,D11) -> 0 | F11: =SUMIFS(F:F, A:A, D11, F:F, ">0") -> 0
C12: Meyliyev.B | D12: 25-17 | E12: =COUNTIF($A$23:$A$830,D12) -> 0 | F12: =SUMIFS(F:F, A:A, D12, F:F, ">0") -> 0
C13: Eshnayev.B | D13: 25-18 | E13: =COUNTIF($A$23:$A$830,D13) -> 0 | F13: =SUMIFS(F:F, A:A, D13, F:F, ">0") -> 0
C14: Shukurova.G | D14: 25-19 | E14: =COUNTIF($A$23:$A$830,D14) -> 0 | F14: =SUMIFS(F:F, A:A, D14, F:F, ">0") -> 0
C15: Maxamadiyev.L | D15: 25-20 | E15: =COUNTIF($A$23:$A$830,D15) -> 0 | F15: =SUMIFS(F:F, A:A, D15, F:F, ">0") -> 0
C16: Eshnayev.B | D16: 25-21 | E16: =COUNTIF($A$23:$A$830,D16) -> 0 | F16: =SUMIFS(F:F, A:A, D16, F:F, ">0") -> 0
... C18: Quldosheva.K | D18: 25-23 | E18: =COUNTIF($A$23:$A$830,D18) -> 0 | F18: =SUMIFS(F:F, A:A, D18, F:F, ">0") -> 0
C19: Jami | E19: =SUM(E5:E18) -> 29 | F19: =SUM(F5:F18) -> 59
C21: Yangilangan sanasi: | D21: 46212
A22: GURUHI | B22: № | C22: Familiiyasi Ismi va Sharfi | D22: Shu vaqtgacha bo'lishi kerak bo'lgan to'lov | E22: Jami | F22: Shu vaqtgacha qarzi
A23: 115 | B23: =COUNTIF($A$23:A23,A23) -> 1 | C23: Abdijamolova Jasmina Jonibek qizi | D23: 17000000 | E23: =10100000 -> 10100000 | F23: =D23-E23 -> 6900000
A24: 116 | B24: =COUNTIF($A$23:A24,A24) -> 1 | C24: Isoqova Gulsevar Sarvar qizi | D24: =8500000+1700000+1700000+1700000+1700000+1700000 -> 17000000 | E24: =8950000+2950000 -> 11900000 | F24: =D24-E24 -> 5100000
A25: 115 | B25: =COUNTIF($A$23:A25,A25) -> 2 | C25: Qayumova Kamola Raxmatullayevna | D25: 17000000 | E25: =12000000 -> 12000000 | F25: =D25-E25 -> 5000000
A26: 115 | B26: =COUNTIF($A$23:A26,A26) -> 3 | C26: Muminova Zebiniso Ergashovna | D26: 17000000 | E26: =10790000+2000000+240000 -> 13030000 | F26: =D26-E26 -> 3970000
A27: 114 | B27: =COUNTIF($A$23:A27,A27) -> 1 | C27: Abdusamadova Laylo Isomiddin qizi | D27: 17000000 | E27: =17000000 -> 17000000 | F27: =D27-E27 -> 0
A28: 114 | B28: =COUNTIF($A$23:A28,A28) -> 2 | C28: Axmadova Zebo Hoshim qizi | D28: 17000000 | E28: =12100000+2000000+2900000 -> 17000000 | F28: =D28-E28 -> 0
A29: 114 | B29: =COUNTIF($A$23:A29,A29) -> 3 | C29: Boymurodova Muxlisa Sherali qizi | D29: 17000000 | E29: =12500000+800000+1000000+2700000 -> 17000000 | F29: =D29-E29 -> 0
A30: 114 | B30: =COUNTIF($A$23:A30,A30) -> 4 | C30: Esanova Madina Jalolovna | D30: 17000000 | E30: =13285000+1500000+2130000+85000 -> 17000000 | F30: =D30-E30 -> 0
A31: 114 | B31: =COUNTIF($A$23:A31,A31) -> 5 | C31: Faxriddinova Charos Faxriddin qizi | D31: 17000000 | E31: =15000000+2000000 -> 17000000 | F31: =D31-E31 -> 0
A32: 114 | B32: =COUNTIF($A$23:A32,A32) -> 6 | C32: G'ayratova Ruxshona Maqsud qizi | D32: 17000000 | E32: =17000000 -> 17000000 | F32: =D32-E32 -> 0
A33: 114 | B33: =COUNTIF($A$23:A33,A33) -> 7 | C33: Jo'raqulova Feruza Axmad qizi | D33: 17000000 | E33: =13000000+4000000 -> 17000000 | F33: =D33-E33 -> 0
A34: 114 | B34: =COUNTIF($A$23:A34,A34) -> 8 | C34: Kenjayeva Durdona Yorqin qizi | D34: 17000000 | E34: =16217000+783000 -> 17000000 | F34: =D34-E34 -> 0
A35: 114 | B35: =COUNTIF($A$23:A35,A35) -> 9 | C35: Mingaliyeva Umida Maratovna | D35: 17000000 | E35: =11500000+4000000+1500000 -> 17000000 | F35: =D35-E35 -> 0
A36: 114 | B36: =COUNTIF($A$23:A36,A36) -> 10 | C36: Mirova Farida Sobirjon qizi | D36: 17000000 | E36: =17000000 -> 17000000 | F36: =D36-E36 -> 0
A37: 114 | B37: =COUNTIF($A$23:A37,A37) -> 11 | C37: Nafasova Sevara Shodiyor qizi | D37: 17000000 | E37: =12425000+1800000+2000000+775000 -> 17000000 | F37: =D37-E37 -> 0
A38: 114 | B38: =COUNTIF($A$23:A38,A38) -> 12 | C38: Narzullayeva Dildora Uroq qizi | D38: 17000000 | E38: =15000000+2000000 -> 17000000 | F38: =D38-E38 -> 0
A39: 114 | B39: =COUNTIF($A$23:A39,A39) -> 13 | C39: Obidjonova Zulayho Obidjon qizi | D39: 17000000 | E39: 17000000 | F39: =D39-E39 -> 0
A40: 114 | B40: =COUNTIF($A$23:A40,A40) -> 14 | C40: Ostonova Shahzoda Xasanovna | D40: 17000000 | E40: =17000000 -> 17000000 | F40: =D40-E40 -> 0
A41: 114 | B41: =COUNTIF($A$23:A41,A41) -> 15 | C41: Qobilova Feruzabonu Xizirali qizi | D41: 17000000 | E41: =12745000+2130000+2125000 -> 17000000 | F41: =D41-E41 -> 0
A42: 114 | B42: =COUNTIF($A$23:A42,A42) -> 16 | C42: Qo'yliyeva Shahzoda Ramon qizi | D42: 17000000 | E42: =8500000+8500000 -> 17000000 | F42: =D42-E42 -> 0
...

Sheet не трогать
C1: =TODAY() -> 46298
B2: Talabalar soni | C2: =SUM(#REF!) -> #REF!
B3: Guruhlar soni | C3: =COUNT(#REF!) -> 0
B4: Umumiy tushum | C4: =SUM(#REF!) -> #REF!
B5: Umumiy qarzdorlik | C5: =SUM(#REF!) -> #REF!
B6: Shartnoma qiymati | C6: =SUM(#REF!) -> #REF!
B18: Guruhlar | C18: Umumiy tushum | D18: Umumiy shartnoma qiymati | E18: Fozida
B19: 101 | C19: =#REF! -> #REF! | D19: =#REF! -> #REF! | E19: =C19/D19 -> #REF! | F19: =IF(E19>99%,"✔","☹") -> #REF!
B20: 102 | C20: =#REF! -> #REF! | D20: =#REF! -> #REF! | E20: =C20/D20 -> #REF! | F20: =IF(E20>99%,"✔","☹") -> #REF!
B21: 103 | C21: =#REF! -> #REF! | D21: =#REF! -> #REF! | E21: =C21/D21 -> #REF! | F21: =IF(E21>99%,"✔","☹") -> #REF!
B22: 104 | C22: =#REF! -> #REF! | D22: =#REF! -> #REF! | E22: =C22/D22 -> #REF! | F22: =IF(E22>99%,"✔","☹") -> #REF!
B23: 105 | C23: =#REF! -> #REF! | D23: =#REF! -> #REF! | E23: =C23/D23 -> #REF! | F23: =IF(E23>99%,"✔","☹") -> #REF!
B24: 106 | C24: =#REF! -> #REF! | D24: =#REF! -> #REF! | E24: =C24/D24 -> #REF! | F24: =IF(E24>99%,"✔","☹") -> #REF!
B25: 107 | C25: =#REF! -> #REF! | D25: =#REF! -> #REF! | E25: =C25/D25 -> #REF! | F25: =IF(E25>99%,"✔","☹") -> #REF!
B26: 108 | C26: =#REF! -> #REF! | D26: =#REF! -> #REF! | E26: =C26/D26 -> #REF! | F26: =IF(E26>99%,"✔","☹") -> #REF!
B27: 113 | C27: =#REF! -> #REF! | D27: =#REF! -> #REF! | E27: =C27/D27 -> #REF! | F27: =IF(E27>99%,"✔","☹") -> #REF!
B28: 114 | C28: =#REF! -> #REF! | D28: =#REF! -> #REF! | E28: =C28/D28 -> #REF! | F28: =IF(E28>99%,"✔","☹") -> #REF!
B29: 115 | C29: =#REF! -> #REF! | D29: =#REF! -> #REF! | E29: =C29/D29 -> #REF! | F29: =IF(E29>99%,"✔","☹") -> #REF!
B30: 116 | C30: =#REF! -> #REF! | D30: =#REF! -> #REF! | E30: =C30/D30 -> #REF! | F30: =IF(E30>99%,"✔","☹") -> #REF!
... B35: 205 | C35: =#REF! -> #REF! | D35: =#REF! -> #REF! | E35: =C35/D35 -> #REF! | F35: =IF(E35>99%,"✔","☹") -> #REF!
C36: =#REF! -> #REF! | D36: =#REF! -> #REF! | E36: =C36/D36 -> #REF! | F36: =IF(E36>99%,"✔","-") -> #REF!
C37: =#REF! -> #REF! | D37: =#REF! -> #REF! | E37: =C37/D37 -> #REF! | F37: =IF(E37>99%,"✔","-") -> #REF!
C38: =#REF! -> #REF! | D38: =#REF! -> #REF! | E38: =C38/D38 -> #REF! | F38: =IF(E38>99%,"✔","-") -> #REF!
C39: =#REF! -> #REF! | D39: =#REF! -> #REF! | E39: =C39/D39 -> #REF! | F39: =IF(E39>99%,"✔","-") -> #REF!
C40: =#REF! -> #REF! | D40: =#REF! -> #REF! | E40: =C40/D40 -> #REF! | F40: =IF(E40>99%,"✔","-") -> #REF!
C41: =#REF! -> #REF! | D41: =#REF! -> #REF! | E41: =C41/D41 -> #REF! | F41: =IF(E41>99%,"✔","-") -> #REF!
C42: =#REF! -> #REF! | D42: =#REF! -> #REF! | E42: =C42/D42 -> #REF! | F42: =IF(E42>99%,"✔","-") -> #REF!
C43: =#REF! -> #REF! | D43: =#REF! -> #REF! | E43: =C43/D43 -> #REF! | F43: =IF(E43>99%,"✔","-") -> #REF!
C44: =#REF! -> #REF! | D44: =#REF! -> #REF! | E44: =C44/D44 -> #REF! | F44: =IF(E44>99%,"✔","-") -> #REF!
C45: =#REF! -> #REF! | D45: =#REF! -> #REF! | E45: =C45/D45 -> #REF! | F45: =IF(E45>99%,"✔","-") -> #REF!
C46: =#REF! -> #REF! | D46: =#REF! -> #REF! | E46: =C46/D46 -> #REF! | F46: =IF(E46>99%,"✔","-") -> #REF!
C47: =#REF! -> #REF! | D47: =#REF! -> #REF! | E47: =C47/D47 -> #REF! | F47: =IF(E47>99%,"✔","-") -> #REF!
... C57: =#REF! -> #REF! | D57: =#REF! -> #REF! | E57: =C57/D57 -> #REF! | F57: =IF(E57>99%,"✔","-") -> #REF!

Sheet KETGAN
A1: ABDURAXMONOVA UMIDA ABDISAMAT QIZI | B1: 114 | C1: 8500000 | D1: 0 | E1: =SUMIFS(#REF!,#REF!,$A1,#REF!,1) -> #REF! | F1: =SUMIFS(#REF!,#REF!,$A1,#REF!,2) -> #REF! | G1: =#REF!-#REF! -> #REF! | H1: =Таблица1[[#This Row],[Shu vaqtgacha bo''lishi kerak bo''lgan to''lov]]-#REF! -> #VALUE!
A2: Alisherova Aziza Alisher qizi | B2: 108 | C2: 0 | D2: 8500000 | E2: =SUMIFS(#REF!,#REF!,$A2,#REF!,1) -> #REF! | F2: =SUMIFS(#REF!,#REF!,$A2,#REF!,2) -> #REF! | G2: =#REF!-#REF! -> #REF! | H2: =Таблица1[[#This Row],[Shu vaqtgacha bo''lishi kerak bo''lgan to''lov]]-#REF! -> #VALUE!
A3: Arzillayeva Dilorom Bahodir qizi | B3: 116 | C3: 8500000 | D3: 8500000 | E3: =SUMIFS(#REF!,#REF!,$A3,#REF!,1) -> #REF! | F3: =SUMIFS(#REF!,#REF!,$A3,#REF!,2) -> #REF! | G3: =#REF!-#REF! -> #REF! | H3: =Таблица1[[#This Row],[Shu vaqtgacha bo''lishi kerak bo''lgan to''lov]]-#REF! -> #VALUE!
A4: Axmatova Muxlisa Asror qizi | B4: 114 | C4: 0 | D4: 8500000 | E4: =SUMIFS(#REF!,#REF!,$A4,#REF!,1) -> #REF! | F4: =SUMIFS(#REF!,#REF!,$A4,#REF!,2) -> #REF! | G4: =#REF!-#REF! -> #REF! | H4: =Таблица1[[#This Row],[Shu vaqtgacha bo''lishi kerak bo''lgan to''lov]]-#REF! -> #VALUE!
A5: Azizova Sevinchoy Shuxrat qizi | B5: 108 | C5: 0 | D5: 8500000 | E5: =SUMIFS(#REF!,#REF!,$A5,#REF!,1) -> #REF! | F5: =SUMIFS(#REF!,#REF!,$A5,#REF!,2) -> #REF! | G5: =#REF!-#REF! -> #REF! | H5: =Таблица1[[#This Row],[Shu vaqtgacha bo''lishi kerak bo''lgan to''lov]]-#REF! -> #VALUE!
A6: Baratova Sabrina Aktam qizi | B6: 108 | C6: 0 | D6: 10750000 | E6: =SUMIFS(#REF!,#REF!,$A6,#REF!,1) -> #REF! | F6: =SUMIFS(#REF!,#REF!,$A6,#REF!,2) -> #REF! | G6: =#REF!-#REF! -> #REF! | H6: =Таблица1[[#This Row],[Shu vaqtgacha bo''lishi kerak bo''lgan to''lov]]-#REF! -> #VALUE!
A7: BERDIYEVA GULCHEHRA ALISHEROVNA | B7: 116 | C7: 8500000 | D7: 0 | E7: =SUMIFS(#REF!,#REF!,$A7,#REF!,1) -> #REF! | F7: =SUMIFS(#REF!,#REF!,$A7,#REF!,2) -> #REF! | G7: =#REF!-#REF! -> #REF! | H7: =Таблица1[[#This Row],[Shu vaqtgacha bo''lishi kerak bo''lgan to''lov]]-#REF! -> #VALUE!
A8: Bozorov Shahzod Azamat o'g'li | B8: 102 | C8: 0 | D8: 8500000 | E8: =SUMIFS(#REF!,#REF!,$A8,#REF!,1) -> #REF! | F8: =SUMIFS(#REF!,#REF!,$A8,#REF!,2) -> #REF! | G8: =#REF!-#REF! -> #REF! | H8: =Таблица1[[#This Row],[Shu vaqtgacha bo''lishi kerak bo''lgan to''lov]]-#REF! -> #VALUE!
A9: HASANOVA MUQADDAS OLIM QIZI | B9: 114 | C9: 8500000 | D9: 0 | E9: =SUMIFS(#REF!,#REF!,$A9,#REF!,1) -> #REF! | F9: =SUMIFS(#REF!,#REF!,$A9,#REF!,2) -> #REF! | G9: =#REF!-#REF! -> #REF! | H9: =Таблица1[[#This Row],[Shu vaqtgacha bo''lishi kerak bo''lgan to''lov]]-#REF! -> #VALUE!
A10: Hazratova Umriniso Komil qizi | B10: 115 | C10: 8500000 | D10: 8500000 | E10: =SUMIFS(#REF!,#REF!,$A10,#REF!,1) -> #REF! | F10: =SUMIFS(#REF!,#REF!,$A10,#REF!,2) -> #REF! | G10: =#REF!-#REF! -> #REF! | H10: =Таблица1[[#This Row],[Shu vaqtgacha bo''lishi kerak bo''lgan to''lov]]-#REF! -> #VALUE!
A11: Inayotova Kumush Farhod qizi | B11: 203 | C11: 8500000 | D11: 0 | E11: =SUMIFS(#REF!,#REF!,$A11,#REF!,1) -> #REF! | F11: =SUMIFS(#REF!,#REF!,$A11,#REF!,2) -> #REF! | G11: =#REF!-#REF! -> #REF! | H11: =Таблица1[[#This Row],[Shu vaqtgacha bo''lishi kerak bo''lgan to''lov]]-#REF! -> #VALUE!
A12: JALILOVA ROXILA SHAMURZAYEVNA | B12: 115 | C12: 8500000 | D12: 0 | E12: =SUMIFS(#REF!,#REF!,$A12,#REF!,1) -> #REF! | F12: =SUMIFS(#REF!,#REF!,$A12,#REF!,2) -> #REF! | G12: =#REF!-#REF! -> #REF! | H12: =Таблица1[[#This Row],[Shu vaqtgacha bo''lishi kerak bo''lgan to''lov]]-#REF! -> #VALUE!
... A24: Yo'ldosheva Barno Zoir qizi | B24: 116 | C24: 0 | D24: 8500000 | E24: =SUMIFS(#REF!,#REF!,$A24,#REF!,1) -> #REF! | F24: =SUMIFS(#REF!,#REF!,$A24,#REF!,2) -> #REF! | G24: =#REF!-#REF! -> #REF! | H24: =Таблица1[[#This Row],[Shu vaqtgacha bo''lishi kerak bo''lgan to''lov]]-#REF! -> #REF!
A25: G'ulomova Sevinch Umurzoq qizi | B25: 103 | C25: 0 | D25: 8500000 | E25: =SUMIFS(#REF!,#REF!,$A25,#REF!,1) -> #REF! | F25: =SUMIFS(#REF!,#REF!,$A25,#REF!,2) -> #REF! | G25: =#REF!-#REF! -> #REF! | H25: =Таблица1[[#This Row],[Shu vaqtgacha bo''lishi kerak bo''lgan to''lov]]-#REF! -> #REF! | I25: +
A26: Nematjonova Marjona Tuychi qizi | B26: 103 | C26: 0 | D26: 8550000 | E26: =SUMIFS(#REF!,#REF!,$A26,#REF!,1) -> #REF! | F26: =SUMIFS(#REF!,#REF!,$A26,#REF!,2) -> #REF! | G26: =#REF!-#REF! -> #REF! | H26: =Таблица1[[#This Row],[Shu vaqtgacha bo''lishi kerak bo''lgan to''lov]]-#REF! -> #REF! | I26: +
A27: Ahmadova Sevinch Lazizjon qizi | B27: 108 | C27: 0 | D27: 8500000 | E27: =SUMIFS(#REF!,#REF!,$A27,#REF!,1) -> #REF! | F27: =SUMIFS(#REF!,#REF!,$A27,#REF!,2) -> #REF! | G27: =#REF!-#REF! -> #REF! | H27: =Таблица1[[#This Row],[Shu vaqtgacha bo''lishi kerak bo''lgan to''lov]]-#REF! -> #REF!
A28: Ubaydullayeva Zuhra Zokir qizi | B28: 108 | C28: 0 | D28: 8500000 | E28: =SUMIFS(#REF!,#REF!,$A28,#REF!,1) -> #REF! | F28: =SUMIFS(#REF!,#REF!,$A28,#REF!,2) -> #REF! | G28: =#REF!-#REF! -> #REF! | H28: =Таблица1[[#This Row],[Shu vaqtgacha bo''lishi kerak bo''lgan to''lov]]-#REF! -> #REF!

Sheet 1 chi kurs
A1: ABDUSAMATOVA LAYLO ISOMIDDIN QIZI | B1: 114 | C1: 8500000 | D1: 0 | E1: =SUMIFS(#REF!,#REF!,$A1,#REF!,1) -> #REF! | F1: =SUMIFS(#REF!,#REF!,$A1,#REF!,2) -> #REF! | G1: =#REF!-#REF! -> #REF! | H1: =Таблица1[[#This Row],[Shu vaqtgacha bo''lishi kerak bo''lgan to''lov]]-#REF! -> #VALUE!
A2: AVAZOVA LOBAR AXTAM QIZI | B2: 114 | C2: 8500000 | D2: 0 | E2: =SUMIFS(#REF!,#REF!,$A2,#REF!,1) -> #REF! | F2: =SUMIFS(#REF!,#REF!,$A2,#REF!,2) -> #REF! | G2: =#REF!-#REF! -> #REF! | H2: =Таблица1[[#This Row],[Shu vaqtgacha bo''lishi kerak bo''lgan to''lov]]-#REF! -> #VALUE!
A3: AHMADOVA ZEBO HOSHIM QIZI | B3: 114 | C3: 8500000 | D3: 0 | E3: =SUMIFS(#REF!,#REF!,$A3,#REF!,1) -> #REF! | F3: =SUMIFS(#REF!,#REF!,$A3,#REF!,2) -> #REF! | G3: =#REF!-#REF! -> #REF! | H3: =Таблица1[[#This Row],[Shu vaqtgacha bo''lishi kerak bo''lgan to''lov]]-#REF! -> #VALUE!
A4: BOYMUROTOVA MUXLISA SHERALI QIZI | B4: 114 | C4: 8500000 | D4: 0 | E4: =SUMIFS(#REF!,#REF!,$A4,#REF!,1) -> #REF! | F4: =SUMIFS(#REF!,#REF!,$A4,#REF!,2) -> #REF! | G4: =#REF!-#REF! -> #REF! | H4: =Таблица1[[#This Row],[Shu vaqtgacha bo''lishi kerak bo''lgan to''lov]]-#REF! -> #VALUE!
A5: CHO‘LLIYEVA SEVINCH AZAMJON QIZI | B5: 114 | C5: 8500000 | D5: 0 | E5: =SUMIFS(#REF!,#REF!,$A5,#REF!,1) -> #REF! | F5: =SUMIFS(#REF!,#REF!,$A5,#REF!,2) -> #REF! | G5: =#REF!-#REF! -> #REF! | H5: =Таблица1[[#This Row],[Shu vaqtgacha bo''lishi kerak bo''lgan to''lov]]-#REF! -> #VALUE!
A6: ESANOVA MADINA JALOL QIZI | B6: 114 | C6: 8500000 | D6: 0 | E6: =SUMIFS(#REF!,#REF!,$A6,#REF!,1) -> #REF! | F6: =SUMIFS(#REF!,#REF!,$A6,#REF!,2) -> #REF! | G6: =#REF!-#REF! -> #REF! | H6: =Таблица1[[#This Row],[Shu vaqtgacha bo''lishi kerak bo''lgan to''lov]]-#REF! -> #VALUE!
A7: FAXRIDDINOVA CHAROS XXX | B7: 114 | C7: 8500000 | D7: 0 | E7: =SUMIFS(#REF!,#REF!,$A7,#REF!,1) -> #REF! | F7: =SUMIFS(#REF!,#REF!,$A7,#REF!,2) -> #REF! | G7: =#REF!-#REF! -> #REF! | H7: =Таблица1[[#This Row],[Shu vaqtgacha bo''lishi kerak bo''lgan to''lov]]-#REF! -> #VALUE!
A8: G‘AYRATOVA RUHSHONA MAQSUD QIZI | B8: 114 | C8: 8500000 | D8: 0 | E8: =SUMIFS(#REF!,#REF!,$A8,#REF!,1) -> #REF! | F8: =SUMIFS(#REF!,#REF!,$A8,#REF!,2) -> #REF! | G8: =#REF!-#REF! -> #REF! | H8: =Таблица1[[#This Row],[Shu vaqtgacha bo''lishi kerak bo''lgan to''lov]]-#REF! -> #VALUE!
A9: JO‘RAQULOVA FERUZA AHMADJON QIZI | B9: 114 | C9: 8500000 | D9: 0 | E9: =SUMIFS(#REF!,#REF!,$A9,#REF!,1) -> #REF! | F9: =SUMIFS(#REF!,#REF!,$A9,#REF!,2) -> #REF! | G9: =#REF!-#REF! -> #REF! | H9: =Таблица1[[#This Row],[Shu vaqtgacha bo''lishi kerak bo''lgan to''lov]]-#REF! -> #VALUE!
A10: MINGALIYEVA UMIDA MARATOVNA | B10: 114 | C10: 8500000 | D10: 0 | E10: =SUMIFS(#REF!,#REF!,$A10,#REF!,1) -> #REF! | F10: =SUMIFS(#REF!,#REF!,$A10,#REF!,2) -> #REF! | G10: =#REF!-#REF! -> #REF! | H10: =Таблица1[[#This Row],[Shu vaqtgacha bo''lishi kerak bo''lgan to''lov]]-#REF! -> #VALUE!
A11: MIROVA FARIDA | B11: 114 | C11: 8500000 | D11: 0 | E11: =SUMIFS(#REF!,#REF!,$A11,#REF!,1) -> #REF! | F11: =SUMIFS(#REF!,#REF!,$A11,#REF!,2) -> #REF! | G11: =#REF!-#REF! -> #REF! | H11: =Таблица1[[#This Row],[Shu vaqtgacha bo''lishi kerak bo''lgan to''lov]]-#REF! -> #VALUE!
A12: NURMATOVA AZIZA RENATOVNA | B12: 114 | C12: 8500000 | D12: 0 | E12: =SUMIFS(#REF!,#REF!,$A12,#REF!,1) -> #REF! | F12: =SUMIFS(#REF!,#REF!,$A12,#REF!,2) -> #REF! | G12: =#REF!-#REF! -> #REF! | H12: =Таблица1[[#This Row],[Shu vaqtgacha bo''lishi kerak bo''lgan to''lov]]-#REF! -> #VALUE!
... A63: Norxo'jayeva Charos Boxodirovna | B63: 206 | C63: 8500000 | D63: 8500000 | E63: =SUMIFS(#REF!,#REF!,$A63,#REF!,1) -> #REF! | F63: =SUMIFS(#REF!,#REF!,$A63,#REF!,2) -> #REF! | G63: =#REF!-#REF! -> #REF! | H63: =Таблица1[[#This Row],[Shu vaqtgacha bo''lishi kerak bo''lgan to''lov]]-#REF! -> #REF!
