Workbook

Sheet bank
A1: Дата | B1: Счет/ИНН | C1: № док-та | D1: Оп | E1: МФО | F1: Оборот Дебет | G1: Оборот Кредит | H1: Назначение платежа | I1: Talabaning F.I.SH | J1: Shartnoma raqami
A2: 9666 | B2: yangi shot | C2: Транзитный счет для разовых платежей 200542744 | D2: 8422272 | E2: 06 | F2: 01048 | G2: 1275000 | H2: 0066708/06/2026й №25/26 Sh/A388 сонли шартномага асосан Toshmurodova Sarvara нинг контракт тулови от TOSHMURODOVA SARVARA | I2: Toshmurodova Sarvara | J2: 25/26 Sh/A 388
A3: 9671 | B3: yangi shot | C3: Транзитный счет для разовых платежей 200542744 | D3: 8557261 | E3: 06 | F3: 01048 | G3: 1200000 | H3: 0065522.06.2026 йилдаги №26/27 SH/A07-сонли шартномага кура Тураева Севинчнинг контракт тулови учун от Юлдошев Суннатилло | I3: Turaeva Sevinch | J3: 26/27 Sh/A 07
A4: 03.07.26 | B4: yangi shot | C4: YULDUZ RAXIMOVA 309016201 | D4: 13498525 | E4: 21 | F4: 01190 | G4: 1275000 | H4: 00667Pirnazariva Jasmina Kontrakt tulovi uchun | I4: Pirnazariva Jasmina
A5: 07.07.26 | B5: yangi shot | C5: Транзитный счет для разовых платежей 200542744 | D5: 8876082 | E5: 06 | F5: 01048 | G5: 1275000 | H5: 0066527.06.2026 й Шартнома№26/27 sh/a 21 га асосан талаба TURAYEVA GULASAL JURA QIZI нинг контракт тулови утказилди от TURAYEVA GULASAL JURA QIZI | I5: Turayeva Gulasal Jura qizi | J5: 26/27 Sh/A 21
A6: 46211 | B6: yangi shot | C6: Транзитный счет для разовых платежей 200542744 | D6: 8921203 | E6: 06 | F6: 01048 | G6: 1000000 | H6: 0065508,07,2026й №26/27 Sh/A 45 шартномага асосан ESHBOBOYEVA FOTIMA NURALI QIZI(AD0697178)нинг контракт тулови от ESHBOBOYEVA FOTIMA | I6: Eshboboyeva Fotima Nurali qizi | J6: 26/27 Sh/A 45
A7: 46213 | B7: yangi shot | C7: Т/счет для спис с ПК физлиц по другим платежам (70 200542744 | D7: 8970168 | E7: 06 | F7: 01048 | G7: 1000000 | H7: 006550065524.06.2026 Y №26/27 SH/A14 SHARTNOMAGA ASOSAN XAMDAMOVA MADINA ABDUQODIR QIZI (AB8517012) NING KONTRAKT TULOVI от MEYLIKOVA MAXFUZA | I7: Xamdamova Madina Abduqodir qizi | J7: 26/27 Sh/A 14
A8: 46224 | B8: yangi shot | C8: Накд пулда бир мартталик туловлар буйича хисоб кит 207215726 | D8: 372517728 | E8: 21 | F8: 01125 | G8: 1000000 | H8: 00995BURIYEVA MOHIRA ABDUG'AFFOR QIZI SHARTNOMAGA ASOSAN KANTRAKT TULOVI UCHUN | I8: Buriyeva Mohira Abdug'affor qizi
A9: 46224 | B9: yangi shot | C9: Транзитный счет для разовых платежей 200542744 | D9: 9186931 | E9: 06 | F9: 01048 | G9: 1275000 | H9: 0066726.06.2026й №26/27 Sh/A20 сонли шартномага асосан Темирбоева Ироданинг контракт тулови утказилди от ТОЖИЕВА КЛАРА | I9: Temirboeva Iroda | J9: 26/27 Sh/A 20
A10: 46226 | B10: yangi shot | C10: Транзитный счет для разовых платежей 200542744 | D10: 9236319 | E10: 06 | F10: 01048 | G10: 1700000 | H10: 0066717.07.2026й №26/27 Sh/A 65 сонли шартномага асосан Исомиддинова Рухшонанинг контракт тулови утказилди от YULDOSHEVA DILNOZA | I10: Isomiddinova Ruxshona | J10: 26/27 Sh/A 65
A11: 46227 | B11: yangi shot | C11: Транзитный счет для разовых платежей 200542744 | D11: 9278872 | E11: 06 | F11: 01048 | G11: 1700000 | H11: 0066718.06.2026й №26/27Sh/A02 сонли шартномага асосан XURRAMOVA SHODIYA AROL QIZI нинг коньракт тулови от XURRAMOVA SHODIYA | I11: Xurramova Shodiya Arol qizi | J11: 26/27 Sh/A 02
A12: 46227 | B12: yangi shot | C12: Транзитный счет для разовых платежей 200542744 | D12: 9268348 | E12: 06 | F12: 01048 | G12: 1275000 | H12: 0065503.07.2026 йилдаги №26/27 SH/A 33-сонли шартномага асосан контракт тулови учун от Ахмадова Муниса | I12: Axmadova Munisa | J12: 26/27 Sh/A 33
A13: 46230 | B13: yangi shot | C13: Чакана амалиётлар кассаси филиал 200542744 | D13: 9292025 | E13: 93 | F13: 01048 | G13: 1700000 | H13: 001420,07,2026й №26/27 Sh/A 79 шартномага асосан UMAROVA IRODA MUZAFFAR QIZI(AE5293914)нинг контракт тулови от Назарова Ойша | I13: Umarova Iroda Muzaffar qizi | J13: 26/27 Sh/A 79
A14: 46230 | B14: yangi shot | C14: Чакана амалиётлар кассаси филиал 200542744 | D14: 9291251 | E14: 93 | F14: 01048 | G14: 1200000 | H14: 001422.06.2026й Шартнома№26/27 sh/a 05 га асосан талаба ESHPULATOAV SHAHNOZA SHERALI QIZIнинг 1-курс 40910203-Хамширалик иши учун контракт тулови утказилди от SHERALIEVA NARGIZA | I14: Eshpulatoav Shahnoza Sherali qizi | J14: 26/27 Sh/A 05
A15: 46230 | B15: yangi shot | C15: Чакана амалиётлар кассаси филиал 200542744 | D15: 9292121 | E15: 93 | F15: 01048 | G15: 1700000 | H15: 001420,07,2026й №26/27 Sh/A 74 шартномага асосан SAYDALIMOVA RUXSHONA SHAROFIDDIN QIZI(AE3352294)нинг контракт тулови от Амонова Сожида | I15: Saydalimova Ruxshona Sharofiddin qizi | J15: 26/27 Sh/A 74
A16: 46231 | B16: yangi shot | C16: Транзитный счет для разовых платежей 200542744 | D16: 9329157 | E16: 06 | F16: 01048 | G16: 1275000 | H16: 0066722.06.2026 йил №26/27 Sh/A 06 шартномага асосан 1-курс талабаси Турабоева Сабринанинг укиши учун тулов от Турабоева Сабрина | I16: Turaboeva Sabrina | J16: 26/27 Sh/A 06
A17: 46231 | B17: yangi shot | C17: Т/счет для спис с ПК физлиц по другим платежам (70 200542744 | D17: 9326135 | E17: 06 | F17: 01048 | G17: 1300000 | H17: 0065522.06.2026й Шартнома№ 26/27 sh/a 11 га асосан талаба Тошева Азиза Шерзод кизининг 1-курс 40910203-Хамширалик иши учун контракт тулови утказилди от TOSHEVA AZIZA | I17: Tosheva Aziza Sherzod qizi | J17: 26/27 Sh/A 11
A18: 46233 | B18: yangi shot | C18: Накд пулда бир мартталик туловлар буйича хисоб кит 207215726 | D18: 372927932 | E18: 21 | F18: 01125 | G18: 1700000 | H18: 00995Meyliqulova Hilola Farhod qizi Kontrakt tulovi | I18: Meyliqulova Hilola Farhod qizi
A19: 46232 | B19: yangi shot | C19: Транзитный счет для разовых платежей 200542744 | D19: 9344988 | E19: 06 | F19: 01048 | G19: 1275000 | H19: 0066703.07.2026йил шартномага асосан Сайфиева Зарина Ахмад Кизи(AD7984192)нинг контракт тулови от МАХМУДОВА ЗАМИРА | I19: Sayfieva Zarina Axmad qizi
A20: 46232 | B20: yangi shot | C20: Транзитный счет для разовых платежей 200542744 | D20: 9346202 | E20: 06 | F20: 01048 | G20: 1300000 | H20: 0066719.06.2026 YILDAGI №26/27 Sh/A 03 SONLI SHARTNOMAGA ASOSAN SAYFILLAYEVA SHODIYONA NING KONTRAKT TO'LOVI O'TKAZILDI (AE4385111) Банка «Ипак Йули»(10111) QARSHI TIBBIYOT TEXNIKUMI NTM от SAYFILLAYEVA SHODIYONA | I20: Sayfillayeva Shodiyona | J20: 26/27 Sh/A 03
A21: 46232 | B21: yangi shot | C21: Транзитный счет для разовых платежей 200542744 | D21: 9350822 | E21: 06 | F21: 01048 | G21: 1200000 | H21: 0065507.07.2026й №26/27 Sh/A 44 шартномага асосан BAHODIROVA ASILA OLMOS QIZI(AE1222596)нинг контракт тулови от SUVONOV OLMOS | I21: Bahodirova Asila Olmos qizi | J21: 26/27 Sh/A 44
A22: 46234 | B22: yangi shot | C22: Транзитный счет для разовых платежей 200542744 | D22: 9402125 | E22: 06 | F22: 01048 | G22: 1700000 | H22: 0066713.07.2026й №26/27 Sh/A55 сонли шартномага асосан QARSHIYEVA SHAHLO нинг контракт тулови утказилди от QARSHIYEVA SHAHLO | I22: Qarshiyeva Shahlo | J22: 26/27 Sh/A 55
A23: 46234 | B23: yangi shot | C23: JURAYEVA DILNOZ G`OIBNAZAROVNA 201055108 | D23: 0000000006 | E23: 06 | F23: 00446 | G23: 1700000 | H23: 00111JURAYEVA DILNOZ GOIBNAZAROVNANING SHARTNOMAGA №26/27 ASOSAN UQISH TULOVI JURAYEVA DILNOZ G`OIBNAZAROVNA | I23: Jurayeva Dilnoz G'oibnazarovna
A24: 46234 | B24: yangi shot | C24: Банк филиалида жисмоний шахслардан бошка бир марта 207243390 | D24: 0199133109 | E24: 06 | F24: 00176 | G24: 2000000 | H24: 00667 Berdimurodova Nafosat AD9709558 kantrakt tulovi uchun | I24: Berdimurodova Nafosat
A25: 46240 | B25: yangi shot | C25: Жисмоний шахслардан накд пул оркали кабул килинган 200836354 | D25: 39634355 | E25: 21 | F25: 00450 | G25: 1700000 | H25: 00111TOSHPULATOVA ASILA №SH/A 112.29.07.2026 SONLI SHARTNOMAGA ASOSAN KANTRAKT TULOVI | I25: Toshpulatova Asila | J25: Sh/A 112
A26: 46240 | B26: yangi shot | C26: Транзитный счет для разовых платежей 200542744 | D26: 9525599 | E26: 06 | F26: 01048 | G26: 1500000 | H26: 0066706.08.2026 YILDAGI № 26/27 SH/A148 SONLI SHARNOMAGA ASOSAN 1-KURS UROQOVA JASMINA JASUR QIZINING KANTRAK TULOVI от UROQOVA JASMINA JASUR QIZI | I26: Uroqova Jasmina Jasur qizi | J26: 26/27 Sh/A 148
A27: 46240 | B27: yangi shot | C27: Транзитный счет для разовых платежей 200542744 | D27: 9533788 | E27: 06 | F27: 01048 | G27: 1700000 | H27: 0066705.08.2026 йилдаги №26/27 Sh/A146 сонли шартномага асосан Samatova Oydin Sulaymonovna ни укиши учун утказилди от Samatova Oydin Sulaymonovna | I27: Samatova Oydin Sulaymonovna | J27: 26/27 Sh/A 146
A28: 46241 | B28: yangi shot | C28: ЧАК 01109 "Китоб" БХМ прочие разовые платежи 201055090 | D28: 13708499 | E28: 21 | F28: 00491 | G28: 1275000 | H28: 00108Xurramova Shahnoza Shuhrat qizi 01.07.2026-yil № 26/27 SH/A 29 shartnomaga asosan kontrakt tulovi | I28: Xurramova Shahnoza Shuhrat qizi | J28: 26/27 Sh/A 29
A29: 46244 | B29: yangi shot | C29: Транзитный счет для разовых платежей 200542744 | D29: 9576140 | E29: 06 | F29: 01048 | G29: 1700000 | H29: 00655ШАМСИЕВА ФОТИМА ШАРТНОМА №26/27 SH/А107 27.07.2026 йилга асосан укиш учун тулов. от ШАМСИЕВА ФОТИМА | I29: Shamsieva Fotima | J29: 26/27 Sh/A 107
A30: 46244 | B30: yangi shot | C30: Транзитный счет для разовых платежей 200542744 | D30: 9587262 | E30: 06 | F30: 01048 | G30: 1700000 | H30: 0065520,07,2026й №26/27 Sh/A 75 шартномага асосан YORBOBOYEVA MAHLIYO XUSAN QIZI(AB9239333)нинг контракт тулови от YORBOBOYEVA MAHLIYO | I30: Yorboboyeva Mahliyo Xusan qizi | J30: 26/27 Sh/A 75
A31: 46244 | B31: yangi shot | C31: Жисмоний шахслардан накд пул оркали кабул килинган 200836354 | D31: 39697033 | E31: 21 | F31: 00450 | G31: 1700000 | H31: 00111XAYDAROVA IRODA ZARIF QIZI №26/27 SH/A 113.29.07.2026 SONLI SHARTNOMAGA ASOSAN KANTRAKT TULOVI | I31: Xaydarova Iroda Zarif qizi | J31: 26/27 Sh/A 113
A32: 46244 | B32: yangi shot | C32: Транзитный счет для разовых платежей 200542744 | D32: 9578359 | E32: 06 | F32: 01048 | G32: 1275000 | H32: 0065529.06.2026й Шартнома№26/27 sh/a 26 га асосан талаба Halimova Sevinch(AD8735102) нинг контракт тулови утказилди от ESHONQULOVA SHAXNOZA | I32: Halimova Sevinch | J32: 26/27 Sh/A 26
A33: 46238 | B33: yangi shot | C33: Транзитный счет для разовых платежей 200542744 | D33: 9469581 | E33: 06 | F33: 01048 | G33: 1700000 | H33: 0066701.08.2026 йил №120 шартномага асосан Махмудова Мафтуна(AE4270256)нинг контракт тулови от ХОЛИКОВ ТУРА | I33: Maxmudova Maftuna | J33: № 120
A34: 46238 | B34: yangi shot | C34: Транзитный счет для разовых платежей 200542744 | D34: 9468067 | E34: 06 | F34: 01048 | G34: 1000000 | H34: 0065511.07.2026 №26/27 SH/A 52 ga asosan Xurramova Sabina (AC3081523) ning kontrakt tulovi uchun от ABDULLAYEV YULDOSH | I34: Xurramova Sabina | J34: 26/27 Sh/A 52
A35: 46245 | B35: yangi shot | C35: Транзитный счет для разовых платежей 200542744 | D35: 9716063 | E35: 06 | F35: 01048 | G35: 1700000 | H35: 0066727.08/2026 йил №108 шартномага асосан Холмахматова Севинчнинг контракт тулови от XOLMAXMATOVA SEVINCH | I35: Xolmaxmatova Sevinch | J35: № 108
A36: 46245 | B36: yangi shot | C36: Транзитный счет для разовых платежей 200542744 | D36: 9708075 | E36: 06 | F36: 01048 | G36: 1700000 | H36: 0066724.07.2026 йил №2627 Sh/A93 шартномага асосан 1-курс талабаси Зарифова Маржона Самижон кизининг укиши учун тулов от ZARIFOVA MARJONA | I36: Zarifova Marjona Samijon qizi | J36: 26/27 Sh/A 93
... A41: 46246 | B41: yangi shot | C41: Транзитный счет для разовых платежей 200542744 | D41: 9740654 | E41: 06 | F41: 01048 | G41: 1700000 | H41: 0066727.07.2026йил №106 шартномага асосан Нумонова Жасмина(АЕ1748671)нинг контракт тулови от ТУРАЕВ БАХОДИР | I41: Numonova Jasmina | J41: № 106
A42: 46247 | B42: yangi shot | C42: Жисмоний шахслардан бир марталик туловлар бош?а бан200547792 | D42: 0069925323 | E42: 06 | F42: 00433 | G42: 1700000 | H42: 00111Суюнова Мафтуна Акбар кизи 1-курс талабаси кантракт тулови | I42: Suyunova Maftuna Akbar qizi
A43: 46248 | B43: yangi shot | C43: Транзитный счет для разовых платежей 200542744 | D43: 9791292 | E43: 06 | F43: 01048 | G43: 1000000 | H43: 00655Худойназарова Озода Илхом кизи шартнома №26/27 sh/А184 14,08,2026 га асосан укиш учун тулов от Худойназарова Озода | I43: Xudoynazarova Ozoda Ilxom qizi | J43: 26/27 Sh/A 184
A44: 46248 | B44: yangi shot | C44: Т/счет для спис с ПК физлиц по другим платежам (70 200542744 | D44: 9791076 | E44: 06 | F44: 01048 | G44: 1000000 | H44: 00655Худойназарова Озода Илхом кизи шартнома №26/27 sh/А184 14,08,2026 га асосан укиш учун тулов. от MUMINOV XUDAYNAZAR | I44: Xudoynazarova Ozoda Ilxom qizi | J44: 26/27 Sh/A 184
...

Sheet не трогать
C1: =TODAY()
B2: Talabalar soni | C2: =SUM(#REF!)
B3: Guruhlar soni | C3: =COUNT(#REF!)
B4: Umumiy tushum | C4: =SUM(#REF!)
B5: Umumiy qarzdorlik | C5: =SUM(#REF!)
B6: Shartnoma qiymati | C6: =SUM(#REF!)
B18: Guruhlar | C18: Umumiy tushum | D18: Umumiy shartnoma qiymati | E18: Fozida
B19: 101 | C19: =#REF! | D19: =#REF! | E19: =C19/D19 | F19: =IF(E19>99%,"✔","☹")
B20: 102 | C20: =#REF! | D20: =#REF! | E20: =C20/D20 | F20: =IF(E20>99%,"✔","☹")
B21: 103 | C21: =#REF! | D21: =#REF! | E21: =C21/D21 | F21: =IF(E21>99%,"✔","☹")
B22: 104 | C22: =#REF! | D22: =#REF! | E22: =C22/D22 | F22: =IF(E22>99%,"✔","☹")
B23: 105 | C23: =#REF! | D23: =#REF! | E23: =C23/D23 | F23: =IF(E23>99%,"✔","☹")
B24: 106 | C24: =#REF! | D24: =#REF! | E24: =C24/D24 | F24: =IF(E24>99%,"✔","☹")
B25: 107 | C25: =#REF! | D25: =#REF! | E25: =C25/D25 | F25: =IF(E25>99%,"✔","☹")
B26: 108 | C26: =#REF! | D26: =#REF! | E26: =C26/D26 | F26: =IF(E26>99%,"✔","☹")
B27: 113 | C27: =#REF! | D27: =#REF! | E27: =C27/D27 | F27: =IF(E27>99%,"✔","☹")
B28: 114 | C28: =#REF! | D28: =#REF! | E28: =C28/D28 | F28: =IF(E28>99%,"✔","☹")
B29: 115 | C29: =#REF! | D29: =#REF! | E29: =C29/D29 | F29: =IF(E29>99%,"✔","☹")
B30: 116 | C30: =#REF! | D30: =#REF! | E30: =C30/D30 | F30: =IF(E30>99%,"✔","☹")
... B35: 205 | C35: =#REF! | D35: =#REF! | E35: =C35/D35 | F35: =IF(E35>99%,"✔","☹")
C36: =#REF! | D36: =#REF! | E36: =C36/D36 | F36: =IF(E36>99%,"✔","-")
C37: =#REF! | D37: =#REF! | E37: =C37/D37 | F37: =IF(E37>99%,"✔","-")
C38: =#REF! | D38: =#REF! | E38: =C38/D38 | F38: =IF(E38>99%,"✔","-")
C39: =#REF! | D39: =#REF! | E39: =C39/D39 | F39: =IF(E39>99%,"✔","-")
C40: =#REF! | D40: =#REF! | E40: =C40/D40 | F40: =IF(E40>99%,"✔","-")
C41: =#REF! | D41: =#REF! | E41: =C41/D41 | F41: =IF(E41>99%,"✔","-")
C42: =#REF! | D42: =#REF! | E42: =C42/D42 | F42: =IF(E42>99%,"✔","-")
C43: =#REF! | D43: =#REF! | E43: =C43/D43 | F43: =IF(E43>99%,"✔","-")
C44: =#REF! | D44: =#REF! | E44: =C44/D44 | F44: =IF(E44>99%,"✔","-")
C45: =#REF! | D45: =#REF! | E45: =C45/D45 | F45: =IF(E45>99%,"✔","-")
C46: =#REF! | D46: =#REF! | E46: =C46/D46 | F46: =IF(E46>99%,"✔","-")
C47: =#REF! | D47: =#REF! | E47: =C47/D47 | F47: =IF(E47>99%,"✔","-")
... C57: =#REF! | D57: =#REF! | E57: =C57/D57 | F57: =IF(E57>99%,"✔","-")

Sheet KETGAN
A1: ABDURAXMONOVA UMIDA ABDISAMAT QIZI | B1: 114 | C1: 8500000 | D1: 0 | E1: =SUMIFS(bank!$G:$G,bank!$I:$I,$A1,bank!$J:$J,1) | F1: =SUMIFS(bank!$G:$G,bank!$I:$I,$A1,bank!$J:$J,2) | G1: =#REF!-#REF! | H1: =#REF!-#REF!
A2: Alisherova Aziza Alisher qizi | B2: 108 | C2: 0 | D2: 8500000 | E2: =SUMIFS(bank!$G:$G,bank!$I:$I,$A2,bank!$J:$J,1) | F2: =SUMIFS(bank!$G:$G,bank!$I:$I,$A2,bank!$J:$J,2) | G2: =#REF!-#REF! | H2: =#REF!-#REF!
A3: Arzillayeva Dilorom Bahodir qizi | B3: 116 | C3: 8500000 | D3: 8500000 | E3: =SUMIFS(bank!$G:$G,bank!$I:$I,$A3,bank!$J:$J,1) | F3: =SUMIFS(bank!$G:$G,bank!$I:$I,$A3,bank!$J:$J,2) | G3: =#REF!-#REF! | H3: =#REF!-#REF!
A4: Axmatova Muxlisa Asror qizi | B4: 114 | C4: 0 | D4: 8500000 | E4: =SUMIFS(bank!$G:$G,bank!$I:$I,$A4,bank!$J:$J,1) | F4: =SUMIFS(bank!$G:$G,bank!$I:$I,$A4,bank!$J:$J,2) | G4: =#REF!-#REF! | H4: =#REF!-#REF!
A5: Azizova Sevinchoy Shuxrat qizi | B5: 108 | C5: 0 | D5: 8500000 | E5: =SUMIFS(bank!$G:$G,bank!$I:$I,$A5,bank!$J:$J,1) | F5: =SUMIFS(bank!$G:$G,bank!$I:$I,$A5,bank!$J:$J,2) | G5: =#REF!-#REF! | H5: =#REF!-#REF!
A6: Baratova Sabrina Aktam qizi | B6: 108 | C6: 0 | D6: 10750000 | E6: =SUMIFS(bank!$G:$G,bank!$I:$I,$A6,bank!$J:$J,1) | F6: =SUMIFS(bank!$G:$G,bank!$I:$I,$A6,bank!$J:$J,2) | G6: =#REF!-#REF! | H6: =#REF!-#REF!
A7: BERDIYEVA GULCHEHRA ALISHEROVNA | B7: 116 | C7: 8500000 | D7: 0 | E7: =SUMIFS(bank!$G:$G,bank!$I:$I,$A7,bank!$J:$J,1) | F7: =SUMIFS(bank!$G:$G,bank!$I:$I,$A7,bank!$J:$J,2) | G7: =#REF!-#REF! | H7: =#REF!-#REF!
A8: Bozorov Shahzod Azamat o'g'li | B8: 102 | C8: 0 | D8: 8500000 | E8: =SUMIFS(bank!$G:$G,bank!$I:$I,$A8,bank!$J:$J,1) | F8: =SUMIFS(bank!$G:$G,bank!$I:$I,$A8,bank!$J:$J,2) | G8: =#REF!-#REF! | H8: =#REF!-#REF!
A9: HASANOVA MUQADDAS OLIM QIZI | B9: 114 | C9: 8500000 | D9: 0 | E9: =SUMIFS(bank!$G:$G,bank!$I:$I,$A9,bank!$J:$J,1) | F9: =SUMIFS(bank!$G:$G,bank!$I:$I,$A9,bank!$J:$J,2) | G9: =#REF!-#REF! | H9: =#REF!-#REF!
A10: Hazratova Umriniso Komil qizi | B10: 115 | C10: 8500000 | D10: 8500000 | E10: =SUMIFS(bank!$G:$G,bank!$I:$I,$A10,bank!$J:$J,1) | F10: =SUMIFS(bank!$G:$G,bank!$I:$I,$A10,bank!$J:$J,2) | G10: =#REF!-#REF! | H10: =#REF!-#REF!
A11: Inayotova Kumush Farhod qizi | B11: 203 | C11: 8500000 | D11: 0 | E11: =SUMIFS(bank!$G:$G,bank!$I:$I,$A11,bank!$J:$J,1) | F11: =SUMIFS(bank!$G:$G,bank!$I:$I,$A11,bank!$J:$J,2) | G11: =#REF!-#REF! | H11: =#REF!-#REF!
A12: JALILOVA ROXILA SHAMURZAYEVNA | B12: 115 | C12: 8500000 | D12: 0 | E12: =SUMIFS(bank!$G:$G,bank!$I:$I,$A12,bank!$J:$J,1) | F12: =SUMIFS(bank!$G:$G,bank!$I:$I,$A12,bank!$J:$J,2) | G12: =#REF!-#REF! | H12: =#REF!-#REF!
... A24: Yo'ldosheva Barno Zoir qizi | B24: 116 | C24: 0 | D24: 8500000 | E24: =SUMIFS(bank!$G:$G,bank!$I:$I,$A24,bank!$J:$J,1) | F24: =SUMIFS(bank!$G:$G,bank!$I:$I,$A24,bank!$J:$J,2) | G24: =#REF!-#REF! | H24: =#REF!-#REF!
A25: G'ulomova Sevinch Umurzoq qizi | B25: 103 | C25: 0 | D25: 8500000 | E25: =SUMIFS(bank!$G:$G,bank!$I:$I,$A25,bank!$J:$J,1) | F25: =SUMIFS(bank!$G:$G,bank!$I:$I,$A25,bank!$J:$J,2) | G25: =#REF!-#REF! | H25: =#REF!-#REF! | I25: +
A26: Nematjonova Marjona Tuychi qizi | B26: 103 | C26: 0 | D26: 8550000 | E26: =SUMIFS(bank!$G:$G,bank!$I:$I,$A26,bank!$J:$J,1) | F26: =SUMIFS(bank!$G:$G,bank!$I:$I,$A26,bank!$J:$J,2) | G26: =#REF!-#REF! | H26: =#REF!-#REF! | I26: +
A27: Ahmadova Sevinch Lazizjon qizi | B27: 108 | C27: 0 | D27: 8500000 | E27: =SUMIFS(bank!$G:$G,bank!$I:$I,$A27,bank!$J:$J,1) | F27: =SUMIFS(bank!$G:$G,bank!$I:$I,$A27,bank!$J:$J,2) | G27: =#REF!-#REF! | H27: =#REF!-#REF!
A28: Ubaydullayeva Zuhra Zokir qizi | B28: 108 | C28: 0 | D28: 8500000 | E28: =SUMIFS(bank!$G:$G,bank!$I:$I,$A28,bank!$J:$J,1) | F28: =SUMIFS(bank!$G:$G,bank!$I:$I,$A28,bank!$J:$J,2) | G28: =#REF!-#REF! | H28: =#REF!-#REF!

Sheet 1 chi kurs
A1: ABDUSAMATOVA LAYLO ISOMIDDIN QIZI | B1: 114 | C1: 8500000 | D1: 0 | E1: =SUMIFS(bank!$G:$G,bank!$I:$I,$A1,bank!$J:$J,1) | F1: =SUMIFS(bank!$G:$G,bank!$I:$I,$A1,bank!$J:$J,2) | G1: =#REF!-#REF! | H1: =#REF!-#REF!
A2: AVAZOVA LOBAR AXTAM QIZI | B2: 114 | C2: 8500000 | D2: 0 | E2: =SUMIFS(bank!$G:$G,bank!$I:$I,$A2,bank!$J:$J,1) | F2: =SUMIFS(bank!$G:$G,bank!$I:$I,$A2,bank!$J:$J,2) | G2: =#REF!-#REF! | H2: =#REF!-#REF!
A3: AHMADOVA ZEBO HOSHIM QIZI | B3: 114 | C3: 8500000 | D3: 0 | E3: =SUMIFS(bank!$G:$G,bank!$I:$I,$A3,bank!$J:$J,1) | F3: =SUMIFS(bank!$G:$G,bank!$I:$I,$A3,bank!$J:$J,2) | G3: =#REF!-#REF! | H3: =#REF!-#REF!
A4: BOYMUROTOVA MUXLISA SHERALI QIZI | B4: 114 | C4: 8500000 | D4: 0 | E4: =SUMIFS(bank!$G:$G,bank!$I:$I,$A4,bank!$J:$J,1) | F4: =SUMIFS(bank!$G:$G,bank!$I:$I,$A4,bank!$J:$J,2) | G4: =#REF!-#REF! | H4: =#REF!-#REF!
A5: CHO‘LLIYEVA SEVINCH AZAMJON QIZI | B5: 114 | C5: 8500000 | D5: 0 | E5: =SUMIFS(bank!$G:$G,bank!$I:$I,$A5,bank!$J:$J,1) | F5: =SUMIFS(bank!$G:$G,bank!$I:$I,$A5,bank!$J:$J,2) | G5: =#REF!-#REF! | H5: =#REF!-#REF!
A6: ESANOVA MADINA JALOL QIZI | B6: 114 | C6: 8500000 | D6: 0 | E6: =SUMIFS(bank!$G:$G,bank!$I:$I,$A6,bank!$J:$J,1) | F6: =SUMIFS(bank!$G:$G,bank!$I:$I,$A6,bank!$J:$J,2) | G6: =#REF!-#REF! | H6: =#REF!-#REF!
A7: FAXRIDDINOVA CHAROS XXX | B7: 114 | C7: 8500000 | D7: 0 | E7: =SUMIFS(bank!$G:$G,bank!$I:$I,$A7,bank!$J:$J,1) | F7: =SUMIFS(bank!$G:$G,bank!$I:$I,$A7,bank!$J:$J,2) | G7: =#REF!-#REF! | H7: =#REF!-#REF!
A8: G‘AYRATOVA RUHSHONA MAQSUD QIZI | B8: 114 | C8: 8500000 | D8: 0 | E8: =SUMIFS(bank!$G:$G,bank!$I:$I,$A8,bank!$J:$J,1) | F8: =SUMIFS(bank!$G:$G,bank!$I:$I,$A8,bank!$J:$J,2) | G8: =#REF!-#REF! | H8: =#REF!-#REF!
A9: JO‘RAQULOVA FERUZA AHMADJON QIZI | B9: 114 | C9: 8500000 | D9: 0 | E9: =SUMIFS(bank!$G:$G,bank!$I:$I,$A9,bank!$J:$J,1) | F9: =SUMIFS(bank!$G:$G,bank!$I:$I,$A9,bank!$J:$J,2) | G9: =#REF!-#REF! | H9: =#REF!-#REF!
A10: MINGALIYEVA UMIDA MARATOVNA | B10: 114 | C10: 8500000 | D10: 0 | E10: =SUMIFS(bank!$G:$G,bank!$I:$I,$A10,bank!$J:$J,1) | F10: =SUMIFS(bank!$G:$G,bank!$I:$I,$A10,bank!$J:$J,2) | G10: =#REF!-#REF! | H10: =#REF!-#REF!
A11: MIROVA FARIDA | B11: 114 | C11: 8500000 | D11: 0 | E11: =SUMIFS(bank!$G:$G,bank!$I:$I,$A11,bank!$J:$J,1) | F11: =SUMIFS(bank!$G:$G,bank!$I:$I,$A11,bank!$J:$J,2) | G11: =#REF!-#REF! | H11: =#REF!-#REF!
A12: NURMATOVA AZIZA RENATOVNA | B12: 114 | C12: 8500000 | D12: 0 | E12: =SUMIFS(bank!$G:$G,bank!$I:$I,$A12,bank!$J:$J,1) | F12: =SUMIFS(bank!$G:$G,bank!$I:$I,$A12,bank!$J:$J,2) | G12: =#REF!-#REF! | H12: =#REF!-#REF!
... A63: Norxo'jayeva Charos Boxodirovna | B63: 206 | C63: 8500000 | D63: 8500000 | E63: =SUMIFS(bank!$G:$G,bank!$I:$I,$A63,bank!$J:$J,1) | F63: =SUMIFS(bank!$G:$G,bank!$I:$I,$A63,bank!$J:$J,2) | G63: =#REF!-#REF! | H63: =#REF!-#REF!
