Workbook

Sheet Xulosa
A1: Shubhali ma'lumotlar tekshiruvi — hisobot
A2: Manba: talabalar_bazasi.json · Tekshiruv sanasi: 26.09.2026 · Rasmiy guruhlar: 26-01, 26-02, 26-03, 26-04, 26-05, 26-06
A4: Tekshirilgan talabalar | B4: 175
A5: Shubhali ma'lumoti bor talabalar | B5: =COUNTA('Talabalar kesimida'!$D$2:$D$41)
A6: Jami topilgan muammolar | B6: =COUNTA('Shubhali ma''lumotlar'!$A$2:$A$59)
A7: Bugun o'zgartirilgan maydonlar | B7: =COUNTA('Bugungi o''zgarishlar'!$A$2:$A$190)
A9: Daraja | B9: 26-01 | C9: 26-02 | D9: 26-03 | E9: 26-04 | F9: 26-05 | G9: 26-06 | H9: Jami
A10: Jiddiy | B10: =SUMPRODUCT(('Shubhali ma''lumotlar'!$B$2:$B$59=$A10)*('Shubhali ma''lumotlar'!$C$2:$C$59=B$9)) | C10: =SUMPRODUCT(('Shubhali ma''lumotlar'!$B$2:$B$59=$A10)*('Shubhali ma''lumotlar'!$C$2:$C$59=C$9)) | D10: =SUMPRODUCT(('Shubhali ma''lumotlar'!$B$2:$B$59=$A10)*('Shubhali ma''lumotlar'!$C$2:$C$59=D$9)) | E10: =SUMPRODUCT(('Shubhali ma''lumotlar'!$B$2:$B$59=$A10)*('Shubhali ma''lumotlar'!$C$2:$C$59=E$9)) | F10: =SUMPRODUCT(('Shubhali ma''lumotlar'!$B$2:$B$59=$A10)*('Shubhali ma''lumotlar'!$C$2:$C$59=F$9)) | G10: =SUMPRODUCT(('Shubhali ma''lumotlar'!$B$2:$B$59=$A10)*('Shubhali ma''lumotlar'!$C$2:$C$59=G$9)) | H10: =SUM(B10:G10)
A11: O'rta | B11: =SUMPRODUCT(('Shubhali ma''lumotlar'!$B$2:$B$59=$A11)*('Shubhali ma''lumotlar'!$C$2:$C$59=B$9)) | C11: =SUMPRODUCT(('Shubhali ma''lumotlar'!$B$2:$B$59=$A11)*('Shubhali ma''lumotlar'!$C$2:$C$59=C$9)) | D11: =SUMPRODUCT(('Shubhali ma''lumotlar'!$B$2:$B$59=$A11)*('Shubhali ma''lumotlar'!$C$2:$C$59=D$9)) | E11: =SUMPRODUCT(('Shubhali ma''lumotlar'!$B$2:$B$59=$A11)*('Shubhali ma''lumotlar'!$C$2:$C$59=E$9)) | F11: =SUMPRODUCT(('Shubhali ma''lumotlar'!$B$2:$B$59=$A11)*('Shubhali ma''lumotlar'!$C$2:$C$59=F$9)) | G11: =SUMPRODUCT(('Shubhali ma''lumotlar'!$B$2:$B$59=$A11)*('Shubhali ma''lumotlar'!$C$2:$C$59=G$9)) | H11: =SUM(B11:G11)
A12: Past | B12: =SUMPRODUCT(('Shubhali ma''lumotlar'!$B$2:$B$59=$A12)*('Shubhali ma''lumotlar'!$C$2:$C$59=B$9)) | C12: =SUMPRODUCT(('Shubhali ma''lumotlar'!$B$2:$B$59=$A12)*('Shubhali ma''lumotlar'!$C$2:$C$59=C$9)) | D12: =SUMPRODUCT(('Shubhali ma''lumotlar'!$B$2:$B$59=$A12)*('Shubhali ma''lumotlar'!$C$2:$C$59=D$9)) | E12: =SUMPRODUCT(('Shubhali ma''lumotlar'!$B$2:$B$59=$A12)*('Shubhali ma''lumotlar'!$C$2:$C$59=E$9)) | F12: =SUMPRODUCT(('Shubhali ma''lumotlar'!$B$2:$B$59=$A12)*('Shubhali ma''lumotlar'!$C$2:$C$59=F$9)) | G12: =SUMPRODUCT(('Shubhali ma''lumotlar'!$B$2:$B$59=$A12)*('Shubhali ma''lumotlar'!$C$2:$C$59=G$9)) | H12: =SUM(B12:G12)
A14: Darajalar izohi
A15: Jiddiy | B15: Ma'lumot aniq xato yoki ziddiyatli (JSHSHIR nazorat raqami, sana/jins mos emas, takror, real bo'lmagan yosh). Qabulga yuborishdan oldin albatta tuzatish kerak.
A16: O'rta | B16: Ma'lumot to'liq emas yoki shubhali (hujjat turi, muassasa, telefon kodi, '+' belgilari, ismlar farqi). Hujjat bilan solishtirish kerak.
A17: Past | B17: Format kamchiligi yoki eslatma (bo'shliqlar, tasdiqlanmagan, bir xil telefon). Shablonda avtomatik tozalandi.
A19: Izoh: 'Bugun o'zgartirilgan' — bugun kiritilgan/o'zgartirilgan ma'lumotlar, git'dagi 559a247 holatiga nisbatan. Telefon raqami bazada faqat ayrim talabalarda bor — bo'sh telefonlar muammo sifatida sanalmagan.

Sheet Shubhali ma'lumotlar
A1: № | B1: Daraja | C1: Guruh | D1: F.I.O | E1: Shartnoma № | F1: Maydon | G1: Kiritilgan qiymat | H1: Muammo | I1: Tavsiya | J1: Bugun o'zgartirilgan
A2: 1 | B2: O'rta | C2: 26-02 | D2: Ro'zimurodova Larisa Ma'matali qizi | E2: 100 | F2: Shahodatnomadagi F.I.O | G2: Ro'zimurodova Larisa Maxmatali qizi | H2: Shahodatnomadagi F.I.O bazadagi F.I.O (Ro'zimurodova Larisa Ma'matali qizi) bilan mos emas | I2: Hujjat asl nusxasi bilan tekshiring
A3: 2 | B3: O'rta | C3: 26-03 | D3: Salayeva Dilroz Muroulla qizi | E3: 205 | F3: Otasining ismi | G3: Muroulla qizi | H3: Ism g'ayrioddiy yozilgan (ehtimol 'Murodulla') | I3: Pasport bilan solishtiring | J3: Ha
A4: 3 | B4: O'rta | C4: 26-03 | D4: Shukurova Zilola Farxod qizi | E4: 172 | F4: Shahodatnomadagi F.I.O | G4: Shukurova Zilola Farhod qizi | H4: Shahodatnomadagi F.I.O bazadagi F.I.O (Shukurova Zilola Farxod qizi) bilan mos emas | I4: Hujjat asl nusxasi bilan tekshiring | J4: Ha
A5: 4 | B5: O'rta | C5: 26-03 | D5: Umirova Sevinch Avlayor qizi | E5: 298 | F5: Hujjat turi | G5: ID-karta | H5: Ta'lim hujjati turi noto'g'ri kiritilgan ('ID-karta') | I5: Shahodatnoma yoki Diplom deb belgilang | J5: Ha
A6: 5 | B6: O'rta | C6: 26-04 | D6: Murodova Ruhshona Ilhomovna | E6: 72 | F6: Shahodatnomadagi F.I.O | G6: Murodova Ruxshona Ilhomovna | H6: Shahodatnomadagi F.I.O bazadagi F.I.O (Murodova Ruhshona Ilhomovna) bilan mos emas | I6: Hujjat asl nusxasi bilan tekshiring | J6: Ha
A7: 6 | B7: O'rta | C7: 26-05 | D7: Choriyeva Zahro Xayrullo qizi | E7: 109 | F7: Shahodatnomadagi F.I.O | G7: Choriyeva Zaxro Xayrullo qizi | H7: Shahodatnomadagi F.I.O bazadagi F.I.O (Choriyeva Zahro Xayrullo qizi) bilan mos emas | I7: Hujjat asl nusxasi bilan tekshiring | J7: Ha
A8: 7 | B8: O'rta | C8: 26-05 | D8: Ergasheva Shabbona Shodmon qizi | E8: 123 | F8: Shahodatnomadagi F.I.O | G8: Ergashova Shabbona Shodmon qizi | H8: Shahodatnomadagi F.I.O bazadagi F.I.O (Ergasheva Shabbona Shodmon qizi) bilan mos emas | I8: Hujjat asl nusxasi bilan tekshiring | J8: Ha
A9: 8 | B9: O'rta | C9: 26-05 | D9: Nazarova Munisa Erkin qizi | E9: 258 | F9: Diplom / shahodatnoma | H9: Ta'lim hujjati seriya-raqami kiritilmagan | I9: Hujjat nusxasidan kiriting
A10: 9 | B10: O'rta | C10: 26-05 | D10: Nazarova Munisa Erkin qizi | E10: 258 | F10: O'qigan muassasa | H10: Avval o'qigan muassasa nomi kiritilmagan | I10: Hujjatdan kiriting
A11: 10 | B11: O'rta | C11: 26-05 | D11: Nazarova Munisa Erkin qizi | E11: 258 | F11: Tugatgan yili | H11: Tugatgan yili kiritilmagan | I11: Hujjatdan kiriting
A12: 11 | B12: O'rta | C12: 26-05 | D12: Xolmirzayeva Zebuniso Xushvaq qizi | E12: 183 | F12: Shahodatnomadagi F.I.O | G12: Xolmirzayeva Zebiniso Xushvaqt qizi | H12: Shahodatnomadagi F.I.O bazadagi F.I.O (Xolmirzayeva Zebuniso Xushvaq qizi) bilan mos emas | I12: Hujjat asl nusxasi bilan tekshiring | J12: Ha
A13: 12 | B13: O'rta | C13: 26-05 | D13: Yuldosheva Ruhshona Xabibullo qizi | E13: 118 | F13: Shahodatnomadagi F.I.O | G13: Yo'ldosheva Ruxshona Xabibullo qizi | H13: Shahodatnomadagi F.I.O bazadagi F.I.O (Yuldosheva Ruhshona Xabibullo qizi) bilan mos emas | I13: Hujjat asl nusxasi bilan tekshiring | J13: Ha
A14: 13 | B14: O'rta | C14: 26-06 | D14: Azimova Zahroxon Abdirauf qizi | E14: 318 | F14: Pasportdagi F.I.O | G14: Azimova Zaxro Abdirouf qizi | H14: Pasportdagi F.I.O bazadagi F.I.O (Azimova Zahroxon Abdirauf qizi) bilan mos emas | I14: Hujjat asl nusxasi bilan tekshiring
A15: 14 | B15: O'rta | C15: 26-06 | D15: Mahmadmurodova Sevara Safarali qizi | E15: 390 | F15: Shahodatnomadagi F.I.O | G15: Mahmamurodova Sevara Safarali qizi | H15: Shahodatnomadagi F.I.O bazadagi F.I.O (Mahmadmurodova Sevara Safarali qizi) bilan mos emas | I15: Hujjat asl nusxasi bilan tekshiring | J15: Ha
A16: 15 | B16: O'rta | C16: 26-06 | D16: Mahmadmurodova Sevara Safarali qizi | E16: 390 | F16: Pasport | G16: AE2103843 | H16: Avvalgi tekshiruvda pasport 'BOSHQA ODAM' deb belgilangan | I16: Pasport nusxasi shu talabaga tegishliligini tasdiqlang | J16: Ha
A17: 16 | B17: O'rta | C17: 26-06 | D17: Sayfieva Sarvinoz Zafar qizi | F17: Pasportdagi F.I.O | G17: Sayfiyeva Sarvinoz Zafar qizi | H17: Pasportdagi F.I.O bazadagi F.I.O (Sayfieva Sarvinoz Zafar qizi) bilan mos emas | I17: Hujjat asl nusxasi bilan tekshiring
A18: 17 | B18: Past | C18: 26-02 | D18: Alimova Sevinch Raxmiddin qizi | E18: 312 | F18: Tasdiq | G18: KUTILMOQDA | H18: Ma'lumotlar hali hujjat bilan tasdiqlanmagan | I18: Hujjat nusxasi bilan solishtirib tasdiqlang | J18: Ha
A19: 18 | B19: Past | C19: 26-02 | D19: Quysinova Rohshona To'lqin qizi | E19: 242 | F19: Telefon | G19: 916397685 | H19: Bir xil telefon raqami: Quysinova Rohshona To'lqin qizi, Xolmamatova Shoxista Sobir qizi, Zayidova Shaboda Sodiqovna | I19: Aka-uka/opa-singil bo'lishi mumkin — tekshiring | J19: Ha
A20: 19 | B20: Past | C20: 26-02 | D20: Quysinova Rohshona To'lqin qizi | E20: 242 | F20: Telefon | G20: 908785105 | H20: Bir xil telefon raqami: Quysinova Rohshona To'lqin qizi, Xolmamatova Shoxista Sobir qizi, Zayidova Shaboda Sodiqovna | I20: Aka-uka/opa-singil bo'lishi mumkin — tekshiring | J20: Ha
A21: 20 | B21: Past | C21: 26-02 | D21: Tursunov Sohibjon Hakim o'g'li | E21: 220 | F21: Telefon | G21: 995658681 | H21: Bir xil telefon raqami: Tursunov Sohibjon Hakim o'g'li, Tursunova Fotima Qosim qizi, Tursunova Zuhra Qosim qizi | I21: Aka-uka/opa-singil bo'lishi mumkin — tekshiring | J21: Ha
A22: 21 | B22: Past | C22: 26-03 | D22: Eshnazarova Dilnoza Rustam qizi | E22: 221 | F22: Yashash viloyat+tumani | G22: PINFL hudud kodi 573 | H22: Yashash hududi aniqlanmadi (muassasa nomida tuman yo'q, PINFL hudud kodi noma'lum) | I22: Shablonda bo'sh qoldirildi — qo'lda kiriting | J22: Ha
A23: 22 | B23: Past | C23: 26-03 | D23: Fayzullayeva Sarvinoz Sherbobo qizi | E23: 152 | F23: Yashash viloyat+tumani | G23: PINFL hudud kodi 573 | H23: Yashash hududi aniqlanmadi (muassasa nomida tuman yo'q, PINFL hudud kodi noma'lum) | I23: Shablonda bo'sh qoldirildi — qo'lda kiriting | J23: Ha
A24: 23 | B24: Past | C24: 26-03 | D24: Izzatulloyeva Vazira G'ayratzoda | E24: 383 | F24: Otasining ismi | G24: G'ayratzoda | H24: Otasining ismi 'qizi / o'g'li' bilan tugamagan | I24: Pasport bilan solishtiring | J24: Ha
A25: 24 | B25: Past | C25: 26-03 | D25: Izzatulloyeva Vazira G'ayratzoda | E25: 383 | F25: Tasdiq | G25: KUTILMOQDA | H25: Ma'lumotlar hali hujjat bilan tasdiqlanmagan | I25: Hujjat nusxasi bilan solishtirib tasdiqlang | J25: Ha
A26: 25 | B26: Past | C26: 26-03 | D26: Niyozova Komila Toshpulatovna | F26: Tasdiq | G26: KUTILMOQDA | H26: Ma'lumotlar hali hujjat bilan tasdiqlanmagan | I26: Hujjat nusxasi bilan solishtirib tasdiqlang
A27: 26 | B27: Past | C27: 26-03 | D27: Primova Husnora Shovkat qizi | E27: 251 | F27: Pasport | G27: AC 0443770 | H27: Pasport raqamida bo'shliq / kichik harf bor | I27: To'g'ri yozilishi: AC0443770 (shablonda tozalandi) | J27: Ha
A28: 27 | B28: Past | C28: 26-03 | D28: Salayeva Dilroz Muroulla qizi | E28: 205 | F28: Yashash viloyat+tumani | G28: PINFL hudud kodi 573 | H28: Yashash hududi aniqlanmadi (muassasa nomida tuman yo'q, PINFL hudud kodi noma'lum) | I28: Shablonda bo'sh qoldirildi — qo'lda kiriting | J28: Ha
A29: 28 | B29: Past | C29: 26-03 | D29: Salayeva Dilroz Muroulla qizi | E29: 205 | F29: Tasdiq | G29: KUTILMOQDA | H29: Ma'lumotlar hali hujjat bilan tasdiqlanmagan | I29: Hujjat nusxasi bilan solishtirib tasdiqlang | J29: Ha
A30: 29 | B30: Past | C30: 26-03 | D30: Shamsiyeva Fotima Sharofiddin qizi | E30: 107 | F30: Yashash viloyat+tumani | G30: PINFL hudud kodi 573 | H30: Yashash hududi aniqlanmadi (muassasa nomida tuman yo'q, PINFL hudud kodi noma'lum) | I30: Shablonda bo'sh qoldirildi — qo'lda kiriting | J30: Ha
A31: 30 | B31: Past | C31: 26-03 | D31: Xolmamatova Shoxista Sobir qizi | E31: 243 | F31: Telefon | G31: 916397685 | H31: Bir xil telefon raqami: Quysinova Rohshona To'lqin qizi, Xolmamatova Shoxista Sobir qizi, Zayidova Shaboda Sodiqovna | I31: Aka-uka/opa-singil bo'lishi mumkin — tekshiring | J31: Ha
A32: 31 | B32: Past | C32: 26-03 | D32: Xolmamatova Shoxista Sobir qizi | E32: 243 | F32: Telefon | G32: 908785105 | H32: Bir xil telefon raqami: Quysinova Rohshona To'lqin qizi, Xolmamatova Shoxista Sobir qizi, Zayidova Shaboda Sodiqovna | I32: Aka-uka/opa-singil bo'lishi mumkin — tekshiring | J32: Ha
A33: 32 | B33: Past | C33: 26-03 | D33: Xolmaxmatova Sevinch Isomiddin qizi | E33: 108 | F33: Yashash viloyat+tumani | G33: PINFL hudud kodi 573 | H33: Yashash hududi aniqlanmadi (muassasa nomida tuman yo'q, PINFL hudud kodi noma'lum) | I33: Shablonda bo'sh qoldirildi — qo'lda kiriting | J33: Ha
A34: 33 | B34: Past | C34: 26-03 | D34: Xurramova Sabina Yuldosh qizi | E34: 52 | F34: Yashash viloyat+tumani | G34: PINFL hudud kodi 823 | H34: Yashash hududi aniqlanmadi (muassasa nomida tuman yo'q, PINFL hudud kodi noma'lum) | I34: Shablonda bo'sh qoldirildi — qo'lda kiriting | J34: Ha
A35: 34 | B35: Past | C35: 26-03 | D35: Xurramova Sabina Yuldosh qizi | E35: 52 | F35: Tasdiq | G35: KUTILMOQDA | H35: Ma'lumotlar hali hujjat bilan tasdiqlanmagan | I35: Hujjat nusxasi bilan solishtirib tasdiqlang | J35: Ha
A36: 35 | B36: Past | C36: 26-04 | D36: Jalolov Javlonbek G'ani o'g'li | E36: 211 | F36: Pasport | G36: AE 4994200 | H36: Pasport raqamida bo'shliq / kichik harf bor | I36: To'g'ri yozilishi: AE4994200 (shablonda tozalandi)
A37: 36 | B37: Past | C37: 26-04 | D37: Nafasova Sevinch Bollijon qizi | E37: 266 | F37: Yashash viloyat+tumani | G37: PINFL hudud kodi 573 | H37: Yashash hududi aniqlanmadi (muassasa nomida tuman yo'q, PINFL hudud kodi noma'lum) | I37: Shablonda bo'sh qoldirildi — qo'lda kiriting
A38: 37 | B38: Past | C38: 26-04 | D38: Ulugbekova Zara Ulug'bek qizi | E38: 313 | F38: Tasdiq | G38: KUTILMOQDA | H38: Ma'lumotlar hali hujjat bilan tasdiqlanmagan | I38: Hujjat nusxasi bilan solishtirib tasdiqlang | J38: Ha
A39: 38 | B39: Past | C39: 26-04 | D39: Xujamuratova Durdona Bahrom qizi | E39: 232 | F39: Tasdiq | G39: KUTILMOQDA | H39: Ma'lumotlar hali hujjat bilan tasdiqlanmagan | I39: Hujjat nusxasi bilan solishtirib tasdiqlang | J39: Ha
A40: 39 | B40: Past | C40: 26-04 | D40: Xurramova Shahnoza Shuhrat qizi | E40: 29 | F40: Telefon | G40: 880096166 | H40: Bir xil telefon raqami: Xurramova Shahnoza Shuhrat qizi, Xurramova Shahrizoda Shuhrat qizi | I40: Aka-uka/opa-singil bo'lishi mumkin — tekshiring
...

Sheet Talabalar kesimida
A1: № | B1: Eng yuqori daraja | C1: Guruh | D1: F.I.O | E1: Muammolar soni | F1: Muammolar | G1: Bugun o'zgartirilgan
A2: 1 | B2: O'rta | C2: 26-02 | D2: Ro'zimurodova Larisa Ma'matali qizi | E2: 1 | F2: • [O'rta] Shahodatnomadagi F.I.O bazadagi F.I.O (Ro'zimurodova Larisa Ma'matali qizi) bilan mos emas
A3: 2 | B3: O'rta | C3: 26-03 | D3: Salayeva Dilroz Muroulla qizi | E3: 3 | F3: • [O'rta] Ism g'ayrioddiy yozilgan (ehtimol 'Murodulla') • [Past] Yashash hududi aniqlanmadi (muassasa nomida tuman yo'q, PINFL hudud kodi noma'lum) • [Past] Ma'lumotlar hali hujjat bilan tasdiqlanmagan | G3: Ha
A4: 3 | B4: O'rta | C4: 26-03 | D4: Shukurova Zilola Farxod qizi | E4: 1 | F4: • [O'rta] Shahodatnomadagi F.I.O bazadagi F.I.O (Shukurova Zilola Farxod qizi) bilan mos emas | G4: Ha
A5: 4 | B5: O'rta | C5: 26-03 | D5: Umirova Sevinch Avlayor qizi | E5: 1 | F5: • [O'rta] Ta'lim hujjati turi noto'g'ri kiritilgan ('ID-karta') | G5: Ha
A6: 5 | B6: O'rta | C6: 26-04 | D6: Murodova Ruhshona Ilhomovna | E6: 1 | F6: • [O'rta] Shahodatnomadagi F.I.O bazadagi F.I.O (Murodova Ruhshona Ilhomovna) bilan mos emas | G6: Ha
A7: 6 | B7: O'rta | C7: 26-05 | D7: Choriyeva Zahro Xayrullo qizi | E7: 1 | F7: • [O'rta] Shahodatnomadagi F.I.O bazadagi F.I.O (Choriyeva Zahro Xayrullo qizi) bilan mos emas | G7: Ha
A8: 7 | B8: O'rta | C8: 26-05 | D8: Ergasheva Shabbona Shodmon qizi | E8: 2 | F8: • [O'rta] Shahodatnomadagi F.I.O bazadagi F.I.O (Ergasheva Shabbona Shodmon qizi) bilan mos emas • [Past] Bir xil telefon raqami: Ergasheva Shabbona Shodmon qizi, Yuldosheva Ruhshona Xabibullo qizi | G8: Ha
A9: 8 | B9: O'rta | C9: 26-05 | D9: Nazarova Munisa Erkin qizi | E9: 4 | F9: • [O'rta] Ta'lim hujjati seriya-raqami kiritilmagan • [O'rta] Avval o'qigan muassasa nomi kiritilmagan • [O'rta] Tugatgan yili kiritilmagan • [Past] Hujjatlar to'liq emas (status: chala)
A10: 9 | B10: O'rta | C10: 26-05 | D10: Xolmirzayeva Zebuniso Xushvaq qizi | E10: 1 | F10: • [O'rta] Shahodatnomadagi F.I.O bazadagi F.I.O (Xolmirzayeva Zebuniso Xushvaq qizi) bilan mos emas | G10: Ha
A11: 10 | B11: O'rta | C11: 26-05 | D11: Yuldosheva Ruhshona Xabibullo qizi | E11: 2 | F11: • [O'rta] Shahodatnomadagi F.I.O bazadagi F.I.O (Yuldosheva Ruhshona Xabibullo qizi) bilan mos emas • [Past] Bir xil telefon raqami: Ergasheva Shabbona Shodmon qizi, Yuldosheva Ruhshona Xabibullo qizi | G11: Ha
A12: 11 | B12: O'rta | C12: 26-06 | D12: Azimova Zahroxon Abdirauf qizi | E12: 1 | F12: • [O'rta] Pasportdagi F.I.O bazadagi F.I.O (Azimova Zahroxon Abdirauf qizi) bilan mos emas
A13: 12 | B13: O'rta | C13: 26-06 | D13: Mahmadmurodova Sevara Safarali qizi | E13: 2 | F13: • [O'rta] Shahodatnomadagi F.I.O bazadagi F.I.O (Mahmadmurodova Sevara Safarali qizi) bilan mos emas • [O'rta] Avvalgi tekshiruvda pasport 'BOSHQA ODAM' deb belgilangan | G13: Ha
A14: 13 | B14: O'rta | C14: 26-06 | D14: Sayfieva Sarvinoz Zafar qizi | E14: 3 | F14: • [O'rta] Pasportdagi F.I.O bazadagi F.I.O (Sayfieva Sarvinoz Zafar qizi) bilan mos emas • [Past] JSHSHIR ichida bo'shliq / ortiqcha belgi bor • [Past] Ma'lumotlar hali hujjat bilan tasdiqlanmagan
A15: 14 | B15: Past | C15: 26-02 | D15: Alimova Sevinch Raxmiddin qizi | E15: 1 | F15: • [Past] Ma'lumotlar hali hujjat bilan tasdiqlanmagan | G15: Ha
A16: 15 | B16: Past | C16: 26-02 | D16: Quysinova Rohshona To'lqin qizi | E16: 2 | F16: • [Past] Bir xil telefon raqami: Quysinova Rohshona To'lqin qizi, Xolmamatova Shoxista Sobir qizi, Zayidova Shaboda Sodiqovna • [Past] Bir xil telefon raqami: Quysinova Rohshona To'lqin qizi, Xolmamatova Shoxista Sobir qizi, Zayidova Shaboda Sodiqovna | G16: Ha
A17: 16 | B17: Past | C17: 26-02 | D17: Tursunov Sohibjon Hakim o'g'li | E17: 1 | F17: • [Past] Bir xil telefon raqami: Tursunov Sohibjon Hakim o'g'li, Tursunova Fotima Qosim qizi, Tursunova Zuhra Qosim qizi | G17: Ha
A18: 17 | B18: Past | C18: 26-03 | D18: Eshnazarova Dilnoza Rustam qizi | E18: 1 | F18: • [Past] Yashash hududi aniqlanmadi (muassasa nomida tuman yo'q, PINFL hudud kodi noma'lum) | G18: Ha
A19: 18 | B19: Past | C19: 26-03 | D19: Fayzullayeva Sarvinoz Sherbobo qizi | E19: 1 | F19: • [Past] Yashash hududi aniqlanmadi (muassasa nomida tuman yo'q, PINFL hudud kodi noma'lum) | G19: Ha
A20: 19 | B20: Past | C20: 26-03 | D20: Izzatulloyeva Vazira G'ayratzoda | E20: 2 | F20: • [Past] Otasining ismi 'qizi / o'g'li' bilan tugamagan • [Past] Ma'lumotlar hali hujjat bilan tasdiqlanmagan | G20: Ha
A21: 20 | B21: Past | C21: 26-03 | D21: Niyozova Komila Toshpulatovna | E21: 1 | F21: • [Past] Ma'lumotlar hali hujjat bilan tasdiqlanmagan
A22: 21 | B22: Past | C22: 26-03 | D22: Primova Husnora Shovkat qizi | E22: 1 | F22: • [Past] Pasport raqamida bo'shliq / kichik harf bor | G22: Ha
A23: 22 | B23: Past | C23: 26-03 | D23: Shamsiyeva Fotima Sharofiddin qizi | E23: 1 | F23: • [Past] Yashash hududi aniqlanmadi (muassasa nomida tuman yo'q, PINFL hudud kodi noma'lum) | G23: Ha
A24: 23 | B24: Past | C24: 26-03 | D24: Xolmamatova Shoxista Sobir qizi | E24: 2 | F24: • [Past] Bir xil telefon raqami: Quysinova Rohshona To'lqin qizi, Xolmamatova Shoxista Sobir qizi, Zayidova Shaboda Sodiqovna • [Past] Bir xil telefon raqami: Quysinova Rohshona To'lqin qizi, Xolmamatova Shoxista Sobir qizi, Zayidova Shaboda Sodiqovna | G24: Ha
A25: 24 | B25: Past | C25: 26-03 | D25: Xolmaxmatova Sevinch Isomiddin qizi | E25: 1 | F25: • [Past] Yashash hududi aniqlanmadi (muassasa nomida tuman yo'q, PINFL hudud kodi noma'lum) | G25: Ha
A26: 25 | B26: Past | C26: 26-03 | D26: Xurramova Sabina Yuldosh qizi | E26: 2 | F26: • [Past] Yashash hududi aniqlanmadi (muassasa nomida tuman yo'q, PINFL hudud kodi noma'lum) • [Past] Ma'lumotlar hali hujjat bilan tasdiqlanmagan | G26: Ha
A27: 26 | B27: Past | C27: 26-04 | D27: Jalolov Javlonbek G'ani o'g'li | E27: 1 | F27: • [Past] Pasport raqamida bo'shliq / kichik harf bor
A28: 27 | B28: Past | C28: 26-04 | D28: Nafasova Sevinch Bollijon qizi | E28: 1 | F28: • [Past] Yashash hududi aniqlanmadi (muassasa nomida tuman yo'q, PINFL hudud kodi noma'lum)
A29: 28 | B29: Past | C29: 26-04 | D29: Ulugbekova Zara Ulug'bek qizi | E29: 1 | F29: • [Past] Ma'lumotlar hali hujjat bilan tasdiqlanmagan | G29: Ha
A30: 29 | B30: Past | C30: 26-04 | D30: Xujamuratova Durdona Bahrom qizi | E30: 1 | F30: • [Past] Ma'lumotlar hali hujjat bilan tasdiqlanmagan | G30: Ha
A31: 30 | B31: Past | C31: 26-04 | D31: Xurramova Shahnoza Shuhrat qizi | E31: 1 | F31: • [Past] Bir xil telefon raqami: Xurramova Shahnoza Shuhrat qizi, Xurramova Shahrizoda Shuhrat qizi
A32: 31 | B32: Past | C32: 26-04 | D32: Xurramova Shahrizoda Shuhrat qizi | E32: 1 | F32: • [Past] Bir xil telefon raqami: Xurramova Shahnoza Shuhrat qizi, Xurramova Shahrizoda Shuhrat qizi | G32: Ha
A33: 32 | B33: Past | C33: 26-04 | D33: Zayidova Shaboda Sodiqovna | E33: 2 | F33: • [Past] Bir xil telefon raqami: Quysinova Rohshona To'lqin qizi, Xolmamatova Shoxista Sobir qizi, Zayidova Shaboda Sodiqovna • [Past] Bir xil telefon raqami: Quysinova Rohshona To'lqin qizi, Xolmamatova Shoxista Sobir qizi, Zayidova Shaboda Sodiqovna | G33: Ha
A34: 33 | B34: Past | C34: 26-05 | D34: Jurayeva Madina Odil qizi | E34: 1 | F34: • [Past] Yashash hududi aniqlanmadi (muassasa nomida tuman yo'q, PINFL hudud kodi noma'lum) | G34: Ha
A35: 34 | B35: Past | C35: 26-05 | D35: Ne'matova Sevinch Hikmatullo qizi | E35: 1 | F35: • [Past] Ma'lumotlar hali hujjat bilan tasdiqlanmagan | G35: Ha
A36: 35 | B36: Past | C36: 26-05 | D36: Tursunova Fotima Qosim qizi | E36: 1 | F36: • [Past] Bir xil telefon raqami: Tursunov Sohibjon Hakim o'g'li, Tursunova Fotima Qosim qizi, Tursunova Zuhra Qosim qizi | G36: Ha
A37: 36 | B37: Past | C37: 26-05 | D37: Tursunova Zuhra Qosim qizi | E37: 1 | F37: • [Past] Bir xil telefon raqami: Tursunov Sohibjon Hakim o'g'li, Tursunova Fotima Qosim qizi, Tursunova Zuhra Qosim qizi | G37: Ha
A38: 37 | B38: Past | C38: 26-06 | D38: Eshimova Zilola Bekzod qizi | E38: 1 | F38: • [Past] Yashash hududi aniqlanmadi (muassasa nomida tuman yo'q, PINFL hudud kodi noma'lum) | G38: Ha
A39: 38 | B39: Past | C39: 26-06 | D39: Niyozova Sevara Turoqulovna | E39: 2 | F39: • [Past] JSHSHIR ichida bo'shliq / ortiqcha belgi bor • [Past] Ma'lumotlar hali hujjat bilan tasdiqlanmagan | G39: Ha
A40: 39 | B40: Past | C40: 26-06 | D40: Sayfillayeva Shodiyona Sayfilla qizi | E40: 1 | F40: • [Past] Yashash hududi aniqlanmadi (muassasa nomida tuman yo'q, PINFL hudud kodi noma'lum)
...

Sheet Bugungi o'zgarishlar
A1: № | B1: Guruh | C1: F.I.O | D1: Maydon | E1: Oldingi qiymat | F1: Yangi qiymat | G1: Shubha bor
A2: 1 | B2: 26-01 | C2: Abdurahmonova Parvinabonu Alisher qizi | D2: Telefon | F2: 885888187 / 902433774
A3: 2 | B3: 26-01 | C3: Arzikulova Amina Salohiddin qizi | D3: Telefon | F3: 953672602
A4: 3 | B4: 26-01 | C4: Hazratova Farzona Toshkand qizi | D4: Telefon | F4: 914606562
A5: 4 | B5: 26-01 | C5: Ibodullayeva Asilzoda Latif qizi | D5: Telefon | F5: 973873803
A6: 5 | B6: 26-01 | C6: Majidova Namuna Shunqor qizi | D6: Telefon | F6: 943387727
A7: 6 | B7: 26-01 | C7: Murodullayev Azizbek Odiljon o'g'li | D7: Telefon | F7: 919490180 / 877511981
A8: 7 | B8: 26-01 | C8: Numonova Jasmina Baxodir qizi | D8: Telefon | F8: 509071311 / 500331311
A9: 8 | B9: 26-01 | C9: Ravshanova Ruhshona Radju qizi | D9: Telefon | F9: 908788108
A10: 9 | B10: 26-01 | C10: Turayeva Dilsuz Oybek qizi | D10: Telefon | F10: 936031585 / 882651585
A11: 10 | B11: 26-01 | C11: Turg'unova Jasmina Turg'un qizi | D11: Telefon | F11: 910707501 / 908698209
A12: 11 | B12: 26-01 | C12: Ziyodullayeva Jasmina Alisher qizi | D12: Telefon | F12: 912240018
A13: 12 | B13: 26-02 | C13: Alimova Sevinch Raxmiddin qizi | D13: Diplom/shahodatnoma | F13: K 5486730 | G13: Ha
A14: 13 | B14: 26-02 | C14: Alimova Sevinch Raxmiddin qizi | D14: Muassasa | F14: Qarshi pedagogika kolleji | G14: Ha
A15: 14 | B15: 26-02 | C15: Alimova Sevinch Raxmiddin qizi | D15: Tugatgan yili | E15: 2024 | F15: 2019 | G15: Ha
A16: 15 | B16: 26-02 | C16: Alimova Sevinch Raxmiddin qizi | D16: Hujjat turi | E16: Shahodatnoma | F16: Diplom | G16: Ha
A17: 16 | B17: 26-02 | C17: Alimova Sevinch Raxmiddin qizi | D17: Holat | E17: chala | F17: full | G17: Ha
A18: 17 | B18: 26-02 | C18: Berdiqulova Gulshan Rustam qizi | D18: Telefon | F18: 770629890
A19: 18 | B19: 26-02 | C19: Eshmurotova Charos Bekqul qizi | D19: Telefon | F19: 886177860 / 914577860
A20: 19 | B20: 26-02 | C20: G'aybullayeva Ruxsora Xusniddin qizi | D20: Telefon | F20: 880052965 / 874861208
A21: 20 | B21: 26-02 | C21: Hamroqulova Farzona Odilovna | D21: Telefon | F21: 870102621
A22: 21 | B22: 26-02 | C22: Hasanova Dilnura Eson qizi | D22: Telefon | F22: 875681508
A23: 22 | B23: 26-02 | C23: Hasanova Marjona Xolmurod qizi | D23: Telefon | F23: 973350582 / 978635082
A24: 23 | B24: 26-02 | C24: Ilhomova Zuhra Davron qizi | D24: Telefon | F24: 881151031 / 881840585
A25: 24 | B25: 26-02 | C25: Islomova Nilufar Abdulxafiz qizi | D25: Telefon | F25: 912174355
A26: 25 | B26: 26-02 | C26: Jalolova Rayxona Akmal qizi | D26: Telefon | F26: 918112208 / 918151309
A27: 26 | B27: 26-02 | C27: Javliyeva Nargiza Ortiq qizi | D27: Telefon | F27: 880880124
A28: 27 | B28: 26-02 | C28: Nu'monova Saidabonu Ulug'bek qizi | D28: Telefon | F28: 975855793 / 776070824
A29: 28 | B29: 26-02 | C29: Ochildiyeva Dinora Otabek qizi | D29: Telefon | F29: 992460829 / 701080829
A30: 29 | B30: 26-02 | C30: Quysinova Rohshona To'lqin qizi | D30: Telefon | F30: 908785105 / 916397685 | G30: Ha
A31: 30 | B31: 26-02 | C31: Samadova Nigora Abdisamiyevna | D31: Telefon | F31: 976312909 / 953332960
A32: 31 | B32: 26-02 | C32: Saydalimova Ruxshona Sharofiddin qizi | D32: Telefon | F32: 770578758 / 704897375
A33: 32 | B33: 26-02 | C33: Shukriyeva Nariye Redvanovna | D33: Telefon | F33: 200132207
A34: 33 | B34: 26-02 | C34: Suyunova Maftuna Akbar qizi | D34: Telefon | F34: 996152272
A35: 34 | B35: 26-02 | C35: To'raboyeva Sabrina Ovlaqul qizi | D35: Telefon | F35: 885890027 / 957701169
A36: 35 | B36: 26-02 | C36: Tosheva Aziza Sherzod qizi | D36: Telefon | F36: 916499228 / 976015200
A37: 36 | B37: 26-02 | C37: To'xtayeva Durdona Nazim qizi | D37: Telefon | F37: 880115819
A38: 37 | B38: 26-02 | C38: Tursunov Sohibjon Hakim o'g'li | D38: Telefon | F38: 995658681 | G38: Ha
A39: 38 | B39: 26-02 | C39: Umarova Iroda Muzaffar qizi | D39: Telefon | F39: 880669272 / 952556670
A40: 39 | B40: 26-02 | C40: Uroqova Jasmina Jasur qizi | D40: Telefon | F40: 334948423 / 991840519
...

Sheet Chiqarilganlar
A1: № | B1: F.I.O | C1: Guruh / holat | D1: JSHSHIR
A2: 1 | B2: Axmedova Saodat Hamro qizi | C2: Talabalar safidan chiqarilganlar | D2: 42504932740019
A3: 2 | B3: G'iyosova Shodiyona Abduqahhor qizi | C3: Talabalar safidan chiqarilganlar | D3: 60202085590030
A4: 3 | B4: Muminova Durdona Anvar qizi | C4: Talabalar safidan chiqarilganlar

Sheet Telefonlar manbasi
A1: № | B1: Guruh | C1: F.I.O | D1: Telefon(lar) | E1: Manba
A2: 1 | B2: 26-01 | C2: Abdijalolova Dilnura Yusufjon qizi | D2: 996810119, 978550581 | E2: Bazadan
A3: 2 | B3: 26-01 | C3: Abdurahmonova Parvinabonu Alisher qizi | D3: 885888187, 902433774 | E3: Bazadan
A4: 3 | B4: 26-01 | C4: Arzikulova Amina Salohiddin qizi | D4: 953672602 | E4: Bazadan
A5: 4 | B5: 26-01 | C5: Azamatova Charos Abdiaziz qizi | E5: Topilmadi
A6: 5 | B6: 26-01 | C6: Hazratova Farzona Toshkand qizi | D6: 914606562 | E6: Bazadan
A7: 6 | B7: 26-01 | C7: Ibodullayeva Asilzoda Latif qizi | D7: 973873803 | E7: Bazadan
A8: 7 | B8: 26-01 | C8: Majidova Namuna Shunqor qizi | D8: 943387727 | E8: Bazadan
A9: 8 | B9: 26-01 | C9: Meliyeva Umida Shavkat qizi | E9: Topilmadi
A10: 9 | B10: 26-01 | C10: Murodullayev Azizbek Odiljon o'g'li | D10: 919490180, 877511981 | E10: Bazadan
A11: 10 | B11: 26-01 | C11: Numonova Jasmina Baxodir qizi | D11: 509071311, 500331311 | E11: Bazadan
A12: 11 | B12: 26-01 | C12: Ravshanova Ruhshona Radju qizi | D12: 908788108 | E12: Bazadan
A13: 12 | B13: 26-01 | C13: Turayeva Dilsuz Oybek qizi | D13: 936031585, 882651585 | E13: Bazadan
A14: 13 | B14: 26-01 | C14: Turg'unova Jasmina Turg'un qizi | D14: 910707501, 908698209 | E14: Bazadan
A15: 14 | B15: 26-01 | C15: Ziyodullayeva Jasmina Alisher qizi | D15: 912240018 | E15: Bazadan
A16: 15 | B16: 26-02 | C16: Alimova Sevinch Raxmiddin qizi | D16: 700343131 | E16: Bazadan
A17: 16 | B17: 26-02 | C17: Berdiqulova Gulshan Rustam qizi | D17: 770629890 | E17: Bazadan
A18: 17 | B18: 26-02 | C18: Eshmurotova Charos Bekqul qizi | D18: 886177860, 914577860 | E18: Bazadan
A19: 18 | B19: 26-02 | C19: G'aybullayeva Ruxsora Xusniddin qizi | D19: 880052965, 874861208 | E19: Bazadan
A20: 19 | B20: 26-02 | C20: Hamroqulova Farzona Odilovna | D20: 870102621 | E20: Bazadan
A21: 20 | B21: 26-02 | C21: Hasanova Dilnura Eson qizi | D21: 875681508 | E21: Bazadan
... A26: 25 | B26: 26-02 | C26: Javliyeva Nargiza Ortiq qizi | D26: 880880124 | E26: Bazadan
A27: 26 | B27: 26-02 | C27: Maxmashoxova Feruza Bekmurod qizi | E27: Topilmadi
A28: 27 | B28: 26-02 | C28: Meyliqulova Hilola Farhod qizi | E28: Topilmadi
A29: 28 | B29: 26-02 | C29: Nu'monova Saidabonu Ulug'bek qizi | D29: 975855793, 776070824 | E29: Bazadan
A30: 29 | B30: 26-02 | C30: Ochildiyeva Dinora Otabek qizi | D30: 992460829, 701080829 | E30: Bazadan
A31: 30 | B31: 26-02 | C31: Quysinova Rohshona To'lqin qizi | D31: 908785105, 916397685 | E31: Bazadan
A32: 31 | B32: 26-02 | C32: Ro'zimurodova Larisa Ma'matali qizi | E32: Topilmadi
A33: 32 | B33: 26-02 | C33: Samadova Nigora Abdisamiyevna | D33: 976312909, 953332960 | E33: Bazadan
A34: 33 | B34: 26-02 | C34: Saydalimova Ruxshona Sharofiddin qizi | D34: 770578758, 704897375 | E34: Bazadan
A35: 34 | B35: 26-02 | C35: Shukriyeva Nariye Redvanovna | D35: 200132207 | E35: Bazadan
A36: 35 | B36: 26-02 | C36: Suyunova Maftuna Akbar qizi | D36: 996152272 | E36: Bazadan
A37: 36 | B37: 26-02 | C37: To'raboyeva Sabrina Ovlaqul qizi | D37: 885890027, 957701169 | E37: Bazadan
A38: 37 | B38: 26-02 | C38: To'xtayeva Durdona Nazim qizi | D38: 880115819 | E38: Bazadan
A39: 38 | B39: 26-02 | C39: Tosheva Aziza Sherzod qizi | D39: 916499228, 976015200 | E39: Bazadan
A40: 39 | B40: 26-02 | C40: Tursunov Sohibjon Hakim o'g'li | D40: 995658681 | E40: Bazadan
A41: 40 | B41: 26-02 | C41: Umarova Iroda Muzaffar qizi | D41: 880669272, 952556670 | E41: Bazadan
A42: 41 | B42: 26-02 | C42: Uroqova Jasmina Jasur qizi | D42: 334948423, 991840519 | E42: Bazadan
A43: 42 | B43: 26-02 | C43: Usmanova Iroda Abdurazzoq qizi | D43: 700720614, 992558990 | E43: Bazadan
A44: 43 | B44: 26-02 | C44: Xurramova Shodiya Arol qizi | D44: 880088028 | E44: Bazadan
...

Sheet Tasdiqlangan istisnolar
A1: № | B1: Guruh | C1: F.I.O | D1: JSHSHIR | E1: Sabab | F1: O'tkazilgan tekshiruv
A2: 1 | B2: 26-02 | C2: Yorboboyeva Mahliyo Xusan qizi | D2: 42207935680042 | E2: Maktabni eksternat tarzida tamomlagan (26.09.2026 da tasdiqlandi) | F2: bitirish_yoshi
